<sdf version='1.7'>
  <world name='default'>
    <light name='sun' type='directional'>
      <cast_shadows>1</cast_shadows>
      <pose>0 0 10 0 -0 0</pose>
      <diffuse>0.8 0.8 0.8 1</diffuse>
      <specular>0.2 0.2 0.2 1</specular>
      <attenuation>
        <range>1000</range>
        <constant>0.9</constant>
        <linear>0.01</linear>
        <quadratic>0.001</quadratic>
      </attenuation>
      <direction>-0.5 0.1 -0.9</direction>
      <spot>
        <inner_angle>0</inner_angle>
        <outer_angle>0</outer_angle>
        <falloff>0</falloff>
      </spot>
    </light>
    <model name='ground_plane'>
      <static>1</static>
      <link name='link'>
        <collision name='collision'>
          <geometry>
            <plane>
              <normal>0 0 1</normal>
              <size>100 100</size>
            </plane>
          </geometry>
          <surface>
            <contact>
              <collide_bitmask>65535</collide_bitmask>
              <ode/>
            </contact>
            <friction>
              <ode>
                <mu>100</mu>
                <mu2>50</mu2>
              </ode>
              <torsional>
                <ode/>
              </torsional>
            </friction>
            <bounce/>
          </surface>
          <max_contacts>10</max_contacts>
        </collision>
        <visual name='visual'>
          <cast_shadows>0</cast_shadows>
          <geometry>
            <plane>
              <normal>0 0 1</normal>
              <size>100 100</size>
            </plane>
          </geometry>
          <material>
            <script>
              <uri>file://media/materials/scripts/gazebo.material</uri>
              <name>Gazebo/Grey</name>
            </script>
          </material>
        </visual>
        <self_collide>0</self_collide>
        <enable_wind>0</enable_wind>
        <kinematic>0</kinematic>
      </link>
    </model>
    <gravity>0 0 -9.8</gravity>
    <magnetic_field>6e-06 2.3e-05 -4.2e-05</magnetic_field>
    <atmosphere type='adiabatic'/>
    <physics type='ode'>
      <max_step_size>0.001</max_step_size>
      <real_time_factor>1</real_time_factor>
      <real_time_update_rate>1000</real_time_update_rate>
    </physics>
    <scene>
      <ambient>0.4 0.4 0.4 1</ambient>
      <background>0.7 0.7 0.7 1</background>
      <shadows>1</shadows>
    </scene>
    <wind/>
    <spherical_coordinates>
      <surface_model>EARTH_WGS84</surface_model>
      <latitude_deg>0</latitude_deg>
      <longitude_deg>0</longitude_deg>
      <elevation>0</elevation>
      <heading_deg>0</heading_deg>
    </spherical_coordinates>
    <state world_name='default'>
      <sim_time>233 713000000</sim_time>
      <real_time>59 292825145</real_time>
      <wall_time>1746890270 311660742</wall_time>
      <iterations>49781</iterations>
      <model name='ground_plane'>
        <pose>0 0 0 0 -0 0</pose>
        <scale>1 1 1</scale>
        <link name='link'>
          <pose>0 0 0 0 -0 0</pose>
          <velocity>0 0 0 0 -0 0</velocity>
          <acceleration>0 0 0 0 -0 0</acceleration>
          <wrench>0 0 0 0 -0 0</wrench>
        </link>
      </model>
      <model name='miro01'>
        <pose>-0.007936 0.124662 0.000364 -2.7e-05 -0.108208 1.58676</pose>
        <scale>1 1 1</scale>
        <link name='miro_body::body'>
          <pose>-0.007936 0.124662 0.000364 -2.7e-05 -0.108208 1.58676</pose>
          <velocity>0.002144 -0.002309 0.000737 -0.044082 -0.064585 0.005809</velocity>
          <acceleration>-0.461755 -0.047267 7.29871 1.85811 1.15353 1.08085</acceleration>
          <wrench>-0.725325 -0.074248 11.4648 0 -0 0</wrench>
        </link>
        <link name='miro_body::wheel_lh'>
          <pose>-0.0079 0.123056 0.000255 -0.00025 -0.070581 1.58775</pose>
          <velocity>-0.000145 -0.002236 -0.002004 -0.044636 -0.030892 0.005903</velocity>
          <acceleration>-2.56949 0.424579 -8.69969 -0.896597 0.522848 2.52806</acceleration>
          <wrench>-0.344418 0.056911 -1.16612 0 -0 0</wrench>
        </link>
        <link name='miro_body::wheel_rh'>
          <pose>-0.007927 0.123361 0.000275 0.000209 -0.077708 1.58594</pose>
          <velocity>3.7e-05 -0.00051 0.003576 -0.003299 -0.032683 0.006556</velocity>
          <acceleration>-2.23101 0.215362 12.2343 -1.30992 -0.143235 0.076496</acceleration>
          <wrench>-0.299046 0.028867 1.63989 0 -0 0</wrench>
        </link>
        <link name='miro_gmbl::gmbl'>
          <pose>-0.007202 0.078554 0.00778 -1.1e-05 0.476516 1.58674</pose>
          <velocity>-0.001305 0.001618 0.000978 0.008622 -0.015523 0.016118</velocity>
          <acceleration>-9.63784 1.59869 3.04131 1.19267 1.54619 -2.68594</acceleration>
          <wrench>-0.378478 0.062781 0.119432 0 -0 0</wrench>
        </link>
        <link name='miro_head::ear_lh'>
          <pose>-0.029366 0.094156 -1.4e-05 0.04389 0.397927 1.44833</pose>
          <velocity>-0.016548 0.000121 0.002993 -0.001803 0.058485 -0.026231</velocity>
          <acceleration>0.721455 2.73863 7.68576 0.520244 0.697411 -1.54599</acceleration>
          <wrench>0.040798 0.154867 0.434622 0 -0 0</wrench>
        </link>
        <link name='miro_head::ear_rh'>
          <pose>0.013994 0.094474 0.000125 -0.042777 0.399479 1.72216</pose>
          <velocity>-0.016435 -0.000998 0.000466 -0.001737 0.057895 -0.026204</velocity>
          <acceleration>0.668395 -1.29131 -1.42681 -2.47241 1.42835 1.48213</acceleration>
          <wrench>0.037797 -0.073022 -0.080685 0 -0 0</wrench>
        </link>
        <link name='miro_head::eyelid_lh'>
          <pose>-0.074773 0.137558 -0.021367 0.288465 0.199605 1.66691</pose>
          <velocity>-0.015844 0.000549 0.005707 -0.004891 0.055175 -0.026337</velocity>
          <acceleration>-2.3337 2.34847 6.47127 1.02881 0.730323 -1.87806</acceleration>
          <wrench>-0.039101 0.039349 0.108426 0 -0 0</wrench>
        </link>
        <link name='miro_head::eyelid_rh'>
          <pose>0.089182 0.168685 -0.022788 -0.406404 0.072478 1.49781</pose>
          <velocity>-0.015205 -0.002362 -0.004029 0.000953 0.05557 -0.026188</velocity>
          <acceleration>-2.31668 -0.398655 0.282549 -0.509341 -0.164376 -1.61467</acceleration>
          <wrench>-0.038816 -0.006679 0.004734 0 -0 0</wrench>
        </link>
        <link name='miro_head::head'>
          <pose>-0.00722 0.07923 0.007439 3.1e-05 0.472739 1.58674</pose>
          <velocity>-0.016333 -0.000412 0.001726 -0.001685 0.05724 -0.025968</velocity>
          <acceleration>-5.62667 0.998144 3.1797 -2.60504 0.356432 1.80429</acceleration>
          <wrench>-1.47306 0.261313 0.832442 0 -0 0</wrench>
        </link>
        <link name='miro_neck::neck'>
          <pose>-0.007199 0.078555 0.007781 -1e-05 0.476514 1.58677</pose>
          <velocity>0.003668 0.001792 0.000998 0.007835 -0.027702 0.039706</velocity>
          <acceleration>-4.7915 2.32149 2.8171 -1.401 -0.193281 1.49247</acceleration>
          <wrench>-0.36127 0.175036 0.212403 0 -0 0</wrench>
        </link>
        <link name='miro_tail::tail'>
          <pose>-0.007963 0.124534 8.3e-05 -4.8e-05 -0.106352 1.58696</pose>
          <velocity>0.002214 -0.002384 0.00063 -0.044899 -0.06398 0.00531</velocity>
          <acceleration>-3.56451 2.25265 15.2027 1.58673 0.720731 -1.43387</acceleration>
          <wrench>-0.20157 0.127385 0.859696 0 -0 0</wrench>
        </link>
        <link name='miro_tail::tail_gmbl'>
          <pose>-0.007934 0.124534 8.3e-05 -2.7e-05 -0.106351 1.58676</pose>
          <velocity>0.002235 -0.002389 0.000625 -0.044967 -0.064245 0.005322</velocity>
          <acceleration>-3.55059 2.24933 15.2123 1.52371 1.22713 -1.38699</acceleration>
          <wrench>-0.200782 0.127198 0.86024 0 -0 0</wrench>
        </link>
      </model>
      <model name='miro02'>
        <pose>1.47009 2.62578 0.000364 3e-05 -0.108204 1.55862</pose>
        <scale>1 1 1</scale>
        <link name='miro_body::body'>
          <pose>1.47009 2.62578 0.000364 3e-05 -0.108204 1.55862</pose>
          <velocity>-0.002219 -4e-06 -0.00017 -0.000946 0.05943 -0.003763</velocity>
          <acceleration>0.656214 -0.064965 -0.085757 2.36385 -0.954738 -0.923955</acceleration>
          <wrench>1.03078 -0.102048 -0.134707 0 -0 0</wrench>
        </link>
        <link name='miro_body::wheel_lh'>
          <pose>1.47009 2.62455 0.00028 -0.000201 -0.079594 1.55938</pose>
          <velocity>-4.2e-05 -0.00028 0.002517 -0.006135 0.027442 -0.003691</velocity>
          <acceleration>2.46156 -0.036042 9.33239 -3.12761 -0.143734 1.16454</acceleration>
          <wrench>0.32995 -0.004831 1.25092 0 -0 0</wrench>
        </link>
        <link name='miro_body::wheel_rh'>
          <pose>1.47006 2.62401 0.000246 0.000252 -0.066931 1.55753</pose>
          <velocity>-6.7e-05 1e-06 -0.002878 -0.001784 0.02713 -0.003562</velocity>
          <acceleration>2.3356 -0.184322 -9.78556 -2.03707 -1.50199 -1.51282</acceleration>
          <wrench>0.313066 -0.024707 -1.31167 0 -0 0</wrench>
        </link>
        <link name='miro_gmbl::gmbl'>
          <pose>1.46953 2.57967 0.007777 9e-06 0.476455 1.55861</pose>
          <velocity>0.000694 6.4e-05 -8.4e-05 -0.000763 0.020131 -0.009241</velocity>
          <acceleration>8.68519 -0.003094 -0.185623 1.12407 -1.42912 1.48977</acceleration>
          <wrench>0.341067 -0.000122 -0.007289 0 -0 0</wrench>
        </link>
        <link name='miro_head::ear_lh'>
          <pose>1.44783 2.59593 -3.4e-05 0.043869 0.39763 1.42027</pose>
          <velocity>0.013097 -0.000125 -0.001194 0.001471 -0.04115 0.025312</velocity>
          <acceleration>-0.412984 -2.6759 -4.07711 0.072551 -0.465596 -1.182</acceleration>
          <wrench>-0.023354 -0.151319 -0.230556 0 -0 0</wrench>
        </link>
        <link name='miro_head::ear_rh'>
          <pose>1.49123 2.59508 8.8e-05 -0.043 0.398985 1.69438</pose>
          <velocity>0.013045 0.000942 0.000597 0.0013 -0.040675 0.025459</velocity>
          <acceleration>-0.25159 2.58457 3.66881 -0.064238 0.513844 -1.10977</acceleration>
          <wrench>-0.014227 0.146155 0.207467 0 -0 0</wrench>
        </link>
        <link name='miro_head::eyelid_lh'>
          <pose>1.40366 2.6406 -0.021377 0.288394 0.199288 1.6388</pose>
          <velocity>0.012184 -0.000623 -0.00306 0.004023 -0.038439 0.025621</velocity>
          <acceleration>1.16293 -1.80449 -2.75696 -0.943573 -1.235 -0.88512</acceleration>
          <wrench>0.019485 -0.030234 -0.046193 0 -0 0</wrench>
        </link>
        <link name='miro_head::eyelid_rh'>
          <pose>1.56842 2.66711 -0.022781 -0.406422 0.07216 1.46971</pose>
          <velocity>0.011532 0.002332 0.003833 -0.001227 -0.038314 0.025469</velocity>
          <acceleration>1.23029 1.76864 2.50554 1.1242 -1.01766 -1.18371</acceleration>
          <wrench>0.020613 0.029634 0.04198 0 -0 0</wrench>
        </link>
        <link name='miro_head::head'>
          <pose>1.46954 2.58039 0.007413 -2.2e-05 0.472422 1.55862</pose>
          <velocity>0.013098 0.000405 -0.000316 0.001418 -0.040254 0.025378</velocity>
          <acceleration>4.82799 -0.037802 -0.165863 0.08801 1.26589 -1.30415</acceleration>
          <wrench>1.26396 -0.009896 -0.043423 0 -0 0</wrench>
        </link>
        <link name='miro_neck::neck'>
          <pose>1.46953 2.57967 0.007778 1.8e-05 0.476448 1.55861</pose>
          <velocity>-0.00347 1.1e-05 -5.6e-05 -0.00118 0.029133 -0.032269</velocity>
          <acceleration>4.39248 0.000984 -0.179755 -2.08244 0.157172 2.17363</acceleration>
          <wrench>0.331184 7.4e-05 -0.013553 0 -0 0</wrench>
        </link>
        <link name='miro_tail::tail'>
          <pose>1.47007 2.62564 6.3e-05 1.9e-05 -0.106219 1.55872</pose>
          <velocity>-0.00229 -2.2e-05 -0.000266 -0.001455 0.058919 -0.003297</velocity>
          <acceleration>3.49301 -0.022709 0.075973 2.6985 -0.453417 2.09525</acceleration>
          <wrench>0.197526 -0.001284 0.004296 0 -0 0</wrench>
        </link>
        <link name='miro_tail::tail_gmbl'>
          <pose>1.47009 2.62564 6.3e-05 3e-05 -0.106218 1.55862</pose>
          <velocity>-0.00231 -1.8e-05 -0.000266 -0.001443 0.059149 -0.003301</velocity>
          <acceleration>3.4853 -0.018502 0.072447 2.75387 -0.89626 2.10054</acceleration>
          <wrench>0.19709 -0.001046 0.004097 0 -0 0</wrench>
        </link>
      </model>
      <light name='sun'>
        <pose>0 0 10 0 -0 0</pose>
      </light>
    </state>
    <gui fullscreen='0'>
      <camera name='user_camera'>
        <pose>0.484835 1.5523 6.80976 3.14159 1.57079 3.14159</pose>
        <view_controller>orbit</view_controller>
        <projection_type>perspective</projection_type>
      </camera>
    </gui>
    <model name='miro01'>
      <frame name='miro_body::__model__' attached_to='miro_body::body'>
        <pose relative_to='__model__'>0 0 0 0 -0 0</pose>
      </frame>
      <link name='miro_body::body'>
        <inertial>
          <pose>-0.06 0 0.05 0 -0 0</pose>
          <mass>1.5708</mass>
          <inertia>
            <ixx>0.00523599</ixx>
            <ixy>0</ixy>
            <ixz>0</ixz>
            <iyy>0.00523599</iyy>
            <iyz>0</iyz>
            <izz>0.00785398</izz>
          </inertia>
        </inertial>
        <visual name='visual_valance'>
          <pose>0 0 0 0 -0 0</pose>
          <geometry>
            <mesh>
              <uri>model://miro_model/meshes/valance.dae</uri>
            </mesh>
          </geometry>
          <material>
            <script>
              <uri>file://media/materials/scripts/gazebo.material</uri>
              <name>Gazebo/Grey</name>
            </script>
          </material>
        </visual>
        <collision name='collision_valance'>
          <pose>0 0 0 0 -0 0</pose>
          <geometry>
            <mesh>
              <uri>model://miro_model/meshes/valance_collision.dae</uri>
            </mesh>
          </geometry>
          <surface>
            <friction>
              <ode>
                <mu>0.1</mu>
                <mu2>0.1</mu2>
              </ode>
              <torsional>
                <ode/>
              </torsional>
            </friction>
            <contact>
              <ode/>
            </contact>
            <bounce/>
          </surface>
          <max_contacts>10</max_contacts>
        </collision>
        <visual name='visual_skirt_lh'>
          <pose>0 0 0 0 -0 0</pose>
          <geometry>
            <mesh>
              <uri>model://miro_model/meshes/skirt_lh.dae</uri>
            </mesh>
          </geometry>
          <material>
            <script>
              <uri>file://media/materials/scripts/gazebo.material</uri>
              <name>Gazebo/Grey</name>
            </script>
          </material>
        </visual>
        <visual name='visual_skirt_rh'>
          <pose>0 0 0 0 -0 0</pose>
          <geometry>
            <mesh>
              <uri>model://miro_model/meshes/skirt_rh.dae</uri>
            </mesh>
          </geometry>
          <material>
            <script>
              <uri>file://media/materials/scripts/gazebo.material</uri>
              <name>Gazebo/Grey</name>
            </script>
          </material>
        </visual>
        <visual name='visual_cliff_sensor_L_asm'>
          <pose>0 0 0 0 -0 0</pose>
          <geometry>
            <mesh>
              <uri>model://miro_model/meshes/cliff_sensor_L_asm.dae</uri>
            </mesh>
          </geometry>
          <material>
            <script>
              <uri>file://media/materials/scripts/gazebo.material</uri>
              <name>Gazebo/DarkGrey</name>
            </script>
          </material>
        </visual>
        <visual name='visual_cliff_sensor_R_asm'>
          <pose>0 0 0 0 -0 0</pose>
          <geometry>
            <mesh>
              <uri>model://miro_model/meshes/cliff_sensor_R_asm.dae</uri>
            </mesh>
          </geometry>
          <material>
            <script>
              <uri>file://media/materials/scripts/gazebo.material</uri>
              <name>Gazebo/DarkGrey</name>
            </script>
          </material>
        </visual>
        <visual name='visual_light_sensor_holder_asm_L'>
          <pose>0 0 0 0 -0 0</pose>
          <geometry>
            <mesh>
              <uri>model://miro_model/meshes/light_sensor_holder_asm_L.dae</uri>
            </mesh>
          </geometry>
          <material>
            <script>
              <uri>file://media/materials/scripts/gazebo.material</uri>
              <name>Gazebo/DarkGrey</name>
            </script>
          </material>
        </visual>
        <visual name='visual_light_sensor_holder_asm_R'>
          <pose>0 0 0 0 -0 0</pose>
          <geometry>
            <mesh>
              <uri>model://miro_model/meshes/light_sensor_holder_asm_R.dae</uri>
            </mesh>
          </geometry>
          <material>
            <script>
              <uri>file://media/materials/scripts/gazebo.material</uri>
              <name>Gazebo/DarkGrey</name>
            </script>
          </material>
        </visual>
        <visual name='visual_body_shell'>
          <pose>0 0 0 0 -0 0</pose>
          <geometry>
            <mesh>
              <uri>model://miro_model/meshes/body_shell.dae</uri>
            </mesh>
          </geometry>
          <material>
            <script>
              <uri>file://media/materials/scripts/gazebo.material</uri>
              <name>Gazebo/White</name>
            </script>
          </material>
        </visual>
        <collision name='collision_body_shell'>
          <pose>0 0 0 0 -0 0</pose>
          <geometry>
            <mesh>
              <uri>model://miro_model/meshes/body_shell_collision.dae</uri>
            </mesh>
          </geometry>
          <surface>
            <friction>
              <ode>
                <mu>0.1</mu>
                <mu2>0.1</mu2>
              </ode>
              <torsional>
                <ode/>
              </torsional>
            </friction>
            <contact>
              <ode/>
            </contact>
            <bounce/>
          </surface>
          <max_contacts>10</max_contacts>
        </collision>
        <visual name='visual_slider'>
          <pose>0 0 0 0 -0 0</pose>
          <geometry>
            <mesh>
              <uri>model://miro_model/meshes/slider.dae</uri>
            </mesh>
          </geometry>
          <material>
            <script>
              <uri>file://media/materials/scripts/gazebo.material</uri>
              <name>Gazebo/DarkGrey</name>
            </script>
          </material>
        </visual>
        <collision name='collision_slider'>
          <pose>-0.1075 0 0.0264 0 -0 0</pose>
          <geometry>
            <sphere>
              <radius>0.015</radius>
            </sphere>
          </geometry>
          <surface>
            <friction>
              <ode>
                <mu>0.01</mu>
                <mu2>0.01</mu2>
              </ode>
              <torsional>
                <ode/>
              </torsional>
            </friction>
            <contact>
              <ode/>
            </contact>
            <bounce/>
          </surface>
          <max_contacts>10</max_contacts>
        </collision>
        <sensor name='acc_body' type='imu'>
          <pose>0 0 0 0 -0 0</pose>
          <always_on>1</always_on>
          <update_rate>50</update_rate>
          <visualize>0</visualize>
          <imu/>
        </sensor>
        <sensor name='cliff_l' type='sonar'>
          <pose>0.062 0.055 0.085 0 -0.52 0</pose>
          <always_on>1</always_on>
          <update_rate>50</update_rate>
          <visualize>0</visualize>
          <sonar>
            <min>0</min>
            <max>0.5</max>
            <radius>0.025</radius>
          </sonar>
        </sensor>
        <sensor name='cliff_r' type='sonar'>
          <pose>0.062 -0.055 0.085 0 -0.52 0</pose>
          <always_on>1</always_on>
          <update_rate>50</update_rate>
          <visualize>0</visualize>
          <sonar>
            <min>0</min>
            <max>0.5</max>
            <radius>0.025</radius>
          </sonar>
        </sensor>
        <sensor name='lightfl' type='camera'>
          <pose>0.055 0.065 0.08 -0 -0.06 0.52</pose>
          <camera>
            <horizontal_fov>1.57</horizontal_fov>
            <image>
              <width>16</width>
              <height>12</height>
            </image>
            <clip>
              <near>0.01</near>
              <far>10</far>
            </clip>
          </camera>
          <always_on>1</always_on>
          <update_rate>5</update_rate>
          <visualize>0</visualize>
        </sensor>
        <sensor name='lightfr' type='camera'>
          <pose>0.055 -0.065 0.08 0 -0.06 -0.52</pose>
          <camera>
            <horizontal_fov>1.57</horizontal_fov>
            <image>
              <width>16</width>
              <height>12</height>
            </image>
            <clip>
              <near>0.01</near>
              <far>10</far>
            </clip>
          </camera>
          <always_on>1</always_on>
          <update_rate>5</update_rate>
          <visualize>0</visualize>
        </sensor>
        <sensor name='lightrl' type='camera'>
          <pose>-0.125 0.072 0.06 0 -0.26 2.61</pose>
          <camera>
            <horizontal_fov>1.57</horizontal_fov>
            <image>
              <width>16</width>
              <height>12</height>
            </image>
            <clip>
              <near>0.01</near>
              <far>10</far>
            </clip>
          </camera>
          <always_on>1</always_on>
          <update_rate>5</update_rate>
          <visualize>0</visualize>
        </sensor>
        <sensor name='lightrr' type='camera'>
          <pose>-0.125 -0.072 0.06 0 -0.26 -2.61</pose>
          <camera>
            <horizontal_fov>1.57</horizontal_fov>
            <image>
              <width>16</width>
              <height>12</height>
            </image>
            <clip>
              <near>0.01</near>
              <far>10</far>
            </clip>
          </camera>
          <always_on>1</always_on>
          <update_rate>5</update_rate>
          <visualize>0</visualize>
        </sensor>
        <pose relative_to='miro_body::__model__'>0 0 0 0 -0 0</pose>
        <self_collide>0</self_collide>
        <enable_wind>0</enable_wind>
        <kinematic>0</kinematic>
      </link>
      <link name='miro_body::wheel_lh'>
        <inertial>
          <pose>0.00063 0.07779 0.044838 0 -0 0</pose>
          <mass>0.134041</mass>
          <inertia>
            <ixx>0.00014298</ixx>
            <ixy>0</ixy>
            <ixz>0</ixz>
            <iyy>0.00014298</iyy>
            <iyz>0</iyz>
            <izz>0.00014298</izz>
          </inertia>
        </inertial>
        <visual name='visual_wheel_tyre_lh'>
          <pose>0 0 0 0 -0 0</pose>
          <geometry>
            <mesh>
              <uri>model://miro_model/meshes/wheel_tyre_lh.dae</uri>
            </mesh>
          </geometry>
          <material>
            <script>
              <uri>file://media/materials/scripts/gazebo.material</uri>
              <name>Gazebo/DarkGrey</name>
            </script>
          </material>
        </visual>
        <collision name='collision_wheel_tyre_lh'>
          <pose>0.00063 0.07779 0.044838 -1.5446 0 0</pose>
          <geometry>
            <cylinder>
              <radius>0.045</radius>
              <length>0.002</length>
            </cylinder>
          </geometry>
          <surface>
            <friction>
              <ode>
                <mu>1</mu>
                <mu2>1</mu2>
              </ode>
              <torsional>
                <ode/>
              </torsional>
            </friction>
            <contact>
              <ode/>
            </contact>
            <bounce/>
          </surface>
          <max_contacts>10</max_contacts>
        </collision>
        <visual name='visual_wheel_rim_lh'>
          <pose>0 0 0 0 -0 0</pose>
          <geometry>
            <mesh>
              <uri>model://miro_model/meshes/wheel_rim_lh.dae</uri>
            </mesh>
          </geometry>
          <material>
            <script>
              <uri>file://media/materials/scripts/gazebo.material</uri>
              <name>Gazebo/Grey</name>
            </script>
          </material>
        </visual>
        <pose relative_to='miro_body::__model__'>0 0 0 0 -0 0</pose>
        <self_collide>0</self_collide>
        <enable_wind>0</enable_wind>
        <kinematic>0</kinematic>
      </link>
      <link name='miro_body::wheel_rh'>
        <inertial>
          <pose>0.00063 -0.07779 0.044838 0 -0 0</pose>
          <mass>0.134041</mass>
          <inertia>
            <ixx>0.00014298</ixx>
            <ixy>0</ixy>
            <ixz>0</ixz>
            <iyy>0.00014298</iyy>
            <iyz>0</iyz>
            <izz>0.00014298</izz>
          </inertia>
        </inertial>
        <visual name='visual_wheel_tyre_rh'>
          <pose>0 0 0 0 -0 0</pose>
          <geometry>
            <mesh>
              <uri>model://miro_model/meshes/wheel_tyre_rh.dae</uri>
            </mesh>
          </geometry>
          <material>
            <script>
              <uri>file://media/materials/scripts/gazebo.material</uri>
              <name>Gazebo/DarkGrey</name>
            </script>
          </material>
        </visual>
        <collision name='collision_wheel_tyre_rh'>
          <pose>0.00063 -0.07779 0.044838 1.5446 -0 0</pose>
          <geometry>
            <cylinder>
              <radius>0.045</radius>
              <length>0.002</length>
            </cylinder>
          </geometry>
          <surface>
            <friction>
              <ode>
                <mu>1</mu>
                <mu2>1</mu2>
              </ode>
              <torsional>
                <ode/>
              </torsional>
            </friction>
            <contact>
              <ode/>
            </contact>
            <bounce/>
          </surface>
          <max_contacts>10</max_contacts>
        </collision>
        <visual name='visual_wheel_rim_rh'>
          <pose>0 0 0 0 -0 0</pose>
          <geometry>
            <mesh>
              <uri>model://miro_model/meshes/wheel_rim_rh.dae</uri>
            </mesh>
          </geometry>
          <material>
            <script>
              <uri>file://media/materials/scripts/gazebo.material</uri>
              <name>Gazebo/Grey</name>
            </script>
          </material>
        </visual>
        <pose relative_to='miro_body::__model__'>0 0 0 0 -0 0</pose>
        <self_collide>0</self_collide>
        <enable_wind>0</enable_wind>
        <kinematic>0</kinematic>
      </link>
      <joint name='miro_body::body_wheel_lh' type='revolute'>
        <pose>0.00063 0.07779 0.044838 0 -0 0</pose>
        <parent>miro_body::body</parent>
        <child>miro_body::wheel_lh</child>
        <axis>
          <xyz>0 0.999657 0.026185</xyz>
          <dynamics>
            <friction>0.1</friction>
            <damping>0.1</damping>
            <spring_reference>0</spring_reference>
            <spring_stiffness>0</spring_stiffness>
          </dynamics>
          <limit>
            <lower>-1e+16</lower>
            <upper>1e+16</upper>
          </limit>
        </axis>
      </joint>
      <joint name='miro_body::body_wheel_rh' type='revolute'>
        <pose>0.00063 -0.07779 0.044838 0 -0 0</pose>
        <parent>miro_body::body</parent>
        <child>miro_body::wheel_rh</child>
        <axis>
          <xyz>0 0.999657 -0.026185</xyz>
          <dynamics>
            <friction>0.1</friction>
            <damping>0.1</damping>
            <spring_reference>0</spring_reference>
            <spring_stiffness>0</spring_stiffness>
          </dynamics>
          <limit>
            <lower>-1e+16</lower>
            <upper>1e+16</upper>
          </limit>
        </axis>
      </joint>
      <frame name='miro_tail::__model__' attached_to='miro_tail::tail_gmbl'>
        <pose relative_to='__model__'>0 0 0 0 -0 0</pose>
      </frame>
      <link name='miro_tail::tail_gmbl'>
        <inertial>
          <pose>-0.143 0 0.085 0 -0 0</pose>
          <mass>0.056549</mass>
          <inertia>
            <ixx>3.393e-05</ixx>
            <ixy>0</ixy>
            <ixz>0</ixz>
            <iyy>3.393e-05</iyy>
            <iyz>0</iyz>
            <izz>3.393e-05</izz>
          </inertia>
        </inertial>
        <pose relative_to='miro_tail::__model__'>0 0 0 0 -0 0</pose>
        <self_collide>0</self_collide>
        <enable_wind>0</enable_wind>
        <kinematic>0</kinematic>
      </link>
      <joint name='miro_tail::body_tail_gmbl' type='revolute'>
        <pose>-0.143 0 0.085 0 -0 0</pose>
        <parent>miro_body::body</parent>
        <child>miro_tail::tail_gmbl</child>
        <axis>
          <xyz>0 1 0</xyz>
          <limit>
            <lower>-1.57</lower>
            <upper>1.57</upper>
          </limit>
          <dynamics>
            <friction>0.01</friction>
            <damping>0.02</damping>
            <spring_reference>0</spring_reference>
            <spring_stiffness>0</spring_stiffness>
          </dynamics>
        </axis>
      </joint>
      <link name='miro_tail::tail'>
        <inertial>
          <pose>-0.143 0 0.085 0 -0 0</pose>
          <mass>0.056549</mass>
          <inertia>
            <ixx>3.393e-05</ixx>
            <ixy>0</ixy>
            <ixz>0</ixz>
            <iyy>3.393e-05</iyy>
            <iyz>0</iyz>
            <izz>3.393e-05</izz>
          </inertia>
        </inertial>
        <visual name='visual_tail'>
          <pose>0 0 0 0 -0 0</pose>
          <geometry>
            <mesh>
              <uri>model://miro_model/meshes/tail.dae</uri>
            </mesh>
          </geometry>
          <material>
            <script>
              <uri>file://media/materials/scripts/gazebo.material</uri>
              <name>Gazebo/Grey</name>
            </script>
          </material>
        </visual>
        <collision name='collision_tail'>
          <pose>0 0 0 0 -0 0</pose>
          <geometry>
            <mesh>
              <uri>model://miro_model/meshes/tail_collision.dae</uri>
            </mesh>
          </geometry>
          <surface>
            <friction>
              <ode>
                <mu>0.1</mu>
                <mu2>0.1</mu2>
              </ode>
              <torsional>
                <ode/>
              </torsional>
            </friction>
            <contact>
              <ode/>
            </contact>
            <bounce/>
          </surface>
          <max_contacts>10</max_contacts>
        </collision>
        <pose relative_to='miro_tail::__model__'>0 0 0 0 -0 0</pose>
        <self_collide>0</self_collide>
        <enable_wind>0</enable_wind>
        <kinematic>0</kinematic>
      </link>
      <joint name='miro_tail::tail_gmbl_tail' type='revolute'>
        <pose>-0.143 0 0.085 0 -0 0</pose>
        <parent>miro_tail::tail_gmbl</parent>
        <child>miro_tail::tail</child>
        <axis>
          <xyz>0 0 1</xyz>
          <limit>
            <lower>-1.57</lower>
            <upper>1.57</upper>
          </limit>
          <dynamics>
            <friction>0.01</friction>
            <damping>0.02</damping>
            <spring_reference>0</spring_reference>
            <spring_stiffness>0</spring_stiffness>
          </dynamics>
        </axis>
      </joint>
      <joint name='body_neck' type='revolute'>
        <pose>-0.002 0 0.081 0 -0 0</pose>
        <parent>miro_body::body</parent>
        <child>miro_neck::neck</child>
        <axis>
          <xyz>0 1 0</xyz>
          <limit>
            <lower>0</lower>
            <upper>1.57</upper>
          </limit>
          <dynamics>
            <spring_stiffness>0.4</spring_stiffness>
            <spring_reference>0</spring_reference>
            <friction>0.01</friction>
            <damping>0.1</damping>
          </dynamics>
        </axis>
      </joint>
      <frame name='miro_neck::__model__' attached_to='miro_neck::neck'>
        <pose relative_to='__model__'>0 0 0 0 -0 0</pose>
      </frame>
      <link name='miro_neck::neck'>
        <inertial>
          <pose>-0.002 0 0.141 0 -0 0</pose>
          <mass>0.075398</mass>
          <inertia>
            <ixx>9.802e-05</ixx>
            <ixy>0</ixy>
            <ixz>0</ixz>
            <iyy>9.802e-05</iyy>
            <iyz>0</iyz>
            <izz>1.508e-05</izz>
          </inertia>
        </inertial>
        <pose relative_to='miro_neck::__model__'>0 0 0 0 -0 0</pose>
        <self_collide>0</self_collide>
        <enable_wind>0</enable_wind>
        <kinematic>0</kinematic>
      </link>
      <joint name='neck_gmbl' type='revolute'>
        <pose>-0.002 0 0.201 0 -0 0</pose>
        <parent>miro_neck::neck</parent>
        <child>miro_gmbl::gmbl</child>
        <axis>
          <xyz>0 0 1</xyz>
          <limit>
            <lower>-1.57</lower>
            <upper>1.57</upper>
          </limit>
          <dynamics>
            <friction>0.01</friction>
            <damping>0.1</damping>
            <spring_reference>0</spring_reference>
            <spring_stiffness>0</spring_stiffness>
          </dynamics>
        </axis>
      </joint>
      <frame name='miro_gmbl::__model__' attached_to='miro_gmbl::gmbl'>
        <pose relative_to='__model__'>0 0 0 0 -0 0</pose>
      </frame>
      <link name='miro_gmbl::gmbl'>
        <inertial>
          <pose>-0.002 0 0.171 0 -0 0</pose>
          <mass>0.03927</mass>
          <inertia>
            <ixx>2.487e-05</ixx>
            <ixy>0</ixy>
            <ixz>0</ixz>
            <iyy>2.487e-05</iyy>
            <iyz>0</iyz>
            <izz>4.909e-05</izz>
          </inertia>
        </inertial>
        <visual name='visual_collar'>
          <pose>0 0 0 0 -0 0</pose>
          <geometry>
            <mesh>
              <uri>model://miro_model/meshes/collar.dae</uri>
            </mesh>
          </geometry>
          <material>
            <script>
              <uri>file://media/materials/scripts/gazebo.material</uri>
              <name>Gazebo/Red</name>
            </script>
          </material>
        </visual>
        <pose relative_to='miro_gmbl::__model__'>0 0 0 0 -0 0</pose>
        <self_collide>0</self_collide>
        <enable_wind>0</enable_wind>
        <kinematic>0</kinematic>
      </link>
      <joint name='gmbl_head' type='revolute'>
        <pose>-0.002 0 0.201 0 -0 0</pose>
        <parent>miro_gmbl::gmbl</parent>
        <child>miro_head::head</child>
        <axis>
          <xyz>0 1 0</xyz>
          <limit>
            <lower>-1.57</lower>
            <upper>1.57</upper>
          </limit>
          <dynamics>
            <spring_stiffness>0.1</spring_stiffness>
            <spring_reference>-0.5</spring_reference>
            <friction>0.01</friction>
            <damping>0.1</damping>
          </dynamics>
        </axis>
      </joint>
      <frame name='miro_head::__model__' attached_to='miro_head::head'>
        <pose relative_to='__model__'>0 0 0 0 -0 0</pose>
      </frame>
      <link name='miro_head::head'>
        <inertial>
          <pose>-0.002 0 0.221 0 -0 0</pose>
          <mass>0.261799</mass>
          <inertia>
            <ixx>0.00043633</ixx>
            <ixy>0</ixy>
            <ixz>0</ixz>
            <iyy>0.00043633</iyy>
            <iyz>0</iyz>
            <izz>0.00043633</izz>
          </inertia>
        </inertial>
        <visual name='visual_head_lower'>
          <pose>0 0 0 0 -0 0</pose>
          <geometry>
            <mesh>
              <uri>model://miro_model/meshes/head_lower.dae</uri>
            </mesh>
          </geometry>
          <material>
            <script>
              <uri>file://media/materials/scripts/gazebo.material</uri>
              <name>Gazebo/White</name>
            </script>
          </material>
        </visual>
        <collision name='collision_head_lower'>
          <pose>0 0 0 0 -0 0</pose>
          <geometry>
            <mesh>
              <uri>model://miro_model/meshes/head_lower_collision.dae</uri>
            </mesh>
          </geometry>
          <surface>
            <friction>
              <ode>
                <mu>0.1</mu>
                <mu2>0.1</mu2>
              </ode>
              <torsional>
                <ode/>
              </torsional>
            </friction>
            <contact>
              <ode/>
            </contact>
            <bounce/>
          </surface>
          <max_contacts>10</max_contacts>
        </collision>
        <visual name='visual_head_upper'>
          <pose>0 0 0 0 -0 0</pose>
          <geometry>
            <mesh>
              <uri>model://miro_model/meshes/head_upper.dae</uri>
            </mesh>
          </geometry>
          <material>
            <script>
              <uri>file://media/materials/scripts/gazebo.material</uri>
              <name>Gazebo/White</name>
            </script>
          </material>
        </visual>
        <collision name='collision_head_upper'>
          <pose>0 0 0 0 -0 0</pose>
          <geometry>
            <mesh>
              <uri>model://miro_model/meshes/head_upper_collision.dae</uri>
            </mesh>
          </geometry>
          <surface>
            <friction>
              <ode>
                <mu>0.1</mu>
                <mu2>0.1</mu2>
              </ode>
              <torsional>
                <ode/>
              </torsional>
            </friction>
            <contact>
              <ode/>
            </contact>
            <bounce/>
          </surface>
          <max_contacts>10</max_contacts>
        </collision>
        <visual name='visual_eyelid_lower_lh'>
          <pose>0 0 0 0 -0 0</pose>
          <geometry>
            <mesh>
              <uri>model://miro_model/meshes/eyelid_lower_lh.dae</uri>
            </mesh>
          </geometry>
          <material>
            <script>
              <uri>file://media/materials/scripts/gazebo.material</uri>
              <name>Gazebo/White</name>
            </script>
          </material>
        </visual>
        <visual name='visual_eyelid_lower_rh'>
          <pose>0 0 0 0 -0 0</pose>
          <geometry>
            <mesh>
              <uri>model://miro_model/meshes/eyelid_lower_rh.dae</uri>
            </mesh>
          </geometry>
          <material>
            <script>
              <uri>file://media/materials/scripts/gazebo.material</uri>
              <name>Gazebo/White</name>
            </script>
          </material>
        </visual>
        <visual name='visual_nose'>
          <pose>0 0 0 0 -0 0</pose>
          <geometry>
            <mesh>
              <uri>model://miro_model/meshes/nose.dae</uri>
            </mesh>
          </geometry>
          <material>
            <script>
              <uri>file://media/materials/scripts/gazebo.material</uri>
              <name>Gazebo/Grey</name>
            </script>
          </material>
        </visual>
        <collision name='collision_nose'>
          <pose>0 0 0 0 -0 0</pose>
          <geometry>
            <mesh>
              <uri>model://miro_model/meshes/nose_collision.dae</uri>
            </mesh>
          </geometry>
          <surface>
            <friction>
              <ode>
                <mu>0.3</mu>
                <mu2>0.3</mu2>
              </ode>
              <torsional>
                <ode/>
              </torsional>
            </friction>
            <contact>
              <ode/>
            </contact>
            <bounce/>
          </surface>
          <max_contacts>10</max_contacts>
        </collision>
        <visual name='visual_1'>
          <pose>0.029 0.033 0.252 0 -0 0</pose>
          <geometry>
            <sphere>
              <radius>0.018</radius>
            </sphere>
          </geometry>
          <material>
            <script>
              <uri>file://media/materials/scripts/gazebo.material</uri>
              <name>Gazebo/White</name>
            </script>
          </material>
        </visual>
        <visual name='visual_2'>
          <pose>0.0315 0.036 0.254 0 -0 0</pose>
          <geometry>
            <sphere>
              <radius>0.015</radius>
            </sphere>
          </geometry>
          <material>
            <script>
              <uri>file://media/materials/scripts/gazebo.material</uri>
              <name>Gazebo/DarkGrey</name>
            </script>
          </material>
        </visual>
        <visual name='visual_3'>
          <pose>0.029 -0.033 0.252 0 -0 0</pose>
          <geometry>
            <sphere>
              <radius>0.018</radius>
            </sphere>
          </geometry>
          <material>
            <script>
              <uri>file://media/materials/scripts/gazebo.material</uri>
              <name>Gazebo/White</name>
            </script>
          </material>
        </visual>
        <visual name='visual_4'>
          <pose>0.0315 -0.036 0.254 0 -0 0</pose>
          <geometry>
            <sphere>
              <radius>0.015</radius>
            </sphere>
          </geometry>
          <material>
            <script>
              <uri>file://media/materials/scripts/gazebo.material</uri>
              <name>Gazebo/DarkGrey</name>
            </script>
          </material>
        </visual>
        <sensor name='eye_l' type='wideanglecamera'>
          <pose>0.0377 0.0431 0.2595 -0.4262 -0.6816 0.6244</pose>
          <camera>
            <horizontal_fov>2.0944</horizontal_fov>
            <image>
              <width>1280</width>
              <height>720</height>
            </image>
            <clip>
              <near>0.006</near>
              <far>100</far>
            </clip>
            <lens>
              <type>custom</type>
              <scale_to_hfov>1</scale_to_hfov>
              <custom_function>
                <c1>2</c1>
                <c2>1.25</c2>
                <c3>0</c3>
                <f>1</f>
                <fun>sin</fun>
              </custom_function>
            </lens>
          </camera>
          <always_on>1</always_on>
          <update_rate>10</update_rate>
          <visualize>0</visualize>
        </sensor>
        <sensor name='eye_r' type='wideanglecamera'>
          <pose>0.0377 -0.0431 0.2595 0.4261 -0.6816 -0.6244</pose>
          <camera>
            <horizontal_fov>2.0944</horizontal_fov>
            <image>
              <width>1280</width>
              <height>720</height>
            </image>
            <clip>
              <near>0.006</near>
              <far>100</far>
            </clip>
            <lens>
              <type>custom</type>
              <scale_to_hfov>1</scale_to_hfov>
              <custom_function>
                <c1>2</c1>
                <c2>1.25</c2>
                <c3>0</c3>
                <f>1</f>
                <fun>sin</fun>
              </custom_function>
            </lens>
          </camera>
          <always_on>1</always_on>
          <update_rate>10</update_rate>
          <visualize>0</visualize>
        </sensor>
        <sensor name='eye_l_narrow' type='camera'>
          <pose>0.0377 0.0431 0.2595 -0.4262 -0.6816 0.6244</pose>
          <camera>
            <horizontal_fov>2.0944</horizontal_fov>
            <image>
              <width>1280</width>
              <height>720</height>
            </image>
            <clip>
              <near>0.006</near>
              <far>100</far>
            </clip>
          </camera>
          <always_on>1</always_on>
          <update_rate>10</update_rate>
          <visualize>0</visualize>
        </sensor>
        <sensor name='eye_r_narrow' type='camera'>
          <pose>0.0377 -0.0431 0.2595 0.4261 -0.6816 -0.6244</pose>
          <camera>
            <horizontal_fov>2.0944</horizontal_fov>
            <image>
              <width>1280</width>
              <height>720</height>
            </image>
            <clip>
              <near>0.006</near>
              <far>100</far>
            </clip>
          </camera>
          <always_on>1</always_on>
          <update_rate>10</update_rate>
          <visualize>0</visualize>
        </sensor>
        <sensor name='gaze' type='camera'>
          <pose>0.0577 0 0.2795 0 -0.785398 0</pose>
          <camera>
            <horizontal_fov>1</horizontal_fov>
            <image>
              <width>1280</width>
              <height>720</height>
            </image>
            <clip>
              <near>0.001</near>
              <far>100</far>
            </clip>
          </camera>
          <always_on>1</always_on>
          <update_rate>10</update_rate>
          <visualize>0</visualize>
        </sensor>
        <sensor name='overhead' type='camera'>
          <pose>0 0 1 0 1.22 0</pose>
          <camera>
            <horizontal_fov>1.0472</horizontal_fov>
            <image>
              <width>1280</width>
              <height>720</height>
            </image>
            <clip>
              <near>0.01</near>
              <far>2</far>
            </clip>
          </camera>
          <always_on>1</always_on>
          <update_rate>10</update_rate>
          <visualize>0</visualize>
        </sensor>
        <sensor name='acc_head' type='imu'>
          <pose>0 0 0 0 -0 0</pose>
          <always_on>1</always_on>
          <update_rate>50</update_rate>
          <visualize>0</visualize>
          <imu/>
        </sensor>
        <sensor name='sonar' type='sonar'>
          <pose>0.1 0 0.235 3.14159 -1.57079 3.14159</pose>
          <always_on>1</always_on>
          <update_rate>50</update_rate>
          <visualize>0</visualize>
          <sonar>
            <min>0</min>
            <max>1</max>
            <radius>0.309</radius>
          </sonar>
        </sensor>
        <pose relative_to='miro_head::__model__'>0 0 0 0 -0 0</pose>
        <self_collide>0</self_collide>
        <enable_wind>0</enable_wind>
        <kinematic>0</kinematic>
      </link>
      <link name='miro_head::eyelid_lh'>
        <inertial>
          <pose>0.029 0.032 0.252 0 -0 0</pose>
          <mass>0.016755</mass>
          <inertia>
            <ixx>4.47e-06</ixx>
            <ixy>0</ixy>
            <ixz>0</ixz>
            <iyy>4.47e-06</iyy>
            <iyz>0</iyz>
            <izz>4.47e-06</izz>
          </inertia>
        </inertial>
        <visual name='visual_eyelid_lh'>
          <pose>0 0 0 0 -0 0</pose>
          <geometry>
            <mesh>
              <uri>model://miro_model/meshes/eyelid_lh.dae</uri>
            </mesh>
          </geometry>
          <material>
            <script>
              <uri>file://media/materials/scripts/gazebo.material</uri>
              <name>Gazebo/White</name>
            </script>
          </material>
        </visual>
        <pose relative_to='miro_head::__model__'>0 0 0 0 -0 0</pose>
        <self_collide>0</self_collide>
        <enable_wind>0</enable_wind>
        <kinematic>0</kinematic>
      </link>
      <link name='miro_head::eyelid_rh'>
        <inertial>
          <pose>0.029 -0.032 0.252 0 -0 0</pose>
          <mass>0.016755</mass>
          <inertia>
            <ixx>4.47e-06</ixx>
            <ixy>0</ixy>
            <ixz>0</ixz>
            <iyy>4.47e-06</iyy>
            <iyz>0</iyz>
            <izz>4.47e-06</izz>
          </inertia>
        </inertial>
        <visual name='visual_eyelid_rh'>
          <pose>0 0 0 0 -0 0</pose>
          <geometry>
            <mesh>
              <uri>model://miro_model/meshes/eyelid_rh.dae</uri>
            </mesh>
          </geometry>
          <material>
            <script>
              <uri>file://media/materials/scripts/gazebo.material</uri>
              <name>Gazebo/White</name>
            </script>
          </material>
        </visual>
        <pose relative_to='miro_head::__model__'>0 0 0 0 -0 0</pose>
        <self_collide>0</self_collide>
        <enable_wind>0</enable_wind>
        <kinematic>0</kinematic>
      </link>
      <joint name='miro_head::head_eyelid_lh' type='revolute'>
        <pose>0.029 0.032 0.252 0 -0 0</pose>
        <parent>miro_head::head</parent>
        <child>miro_head::eyelid_lh</child>
        <axis>
          <xyz>-0.675 0.675 -0.2978</xyz>
          <limit>
            <lower>-1.57</lower>
            <upper>1.57</upper>
          </limit>
          <dynamics>
            <friction>0.1</friction>
            <damping>0.1</damping>
            <spring_reference>-0.5</spring_reference>
            <spring_stiffness>0.02</spring_stiffness>
          </dynamics>
        </axis>
        <physics>
          <ode>
            <cfm_damping>1</cfm_damping>
            <implicit_spring_damper>1</implicit_spring_damper>
            <limit>
              <cfm>0</cfm>
              <erp>0.2</erp>
            </limit>
          </ode>
        </physics>
      </joint>
      <joint name='miro_head::head_eyelid_rh' type='revolute'>
        <pose>0.029 -0.032 0.252 0 -0 0</pose>
        <parent>miro_head::head</parent>
        <child>miro_head::eyelid_rh</child>
        <axis>
          <xyz>0.675 0.675 0.2978</xyz>
          <limit>
            <lower>-1.57</lower>
            <upper>1.57</upper>
          </limit>
          <dynamics>
            <friction>0.1</friction>
            <damping>0.1</damping>
            <spring_reference>-0.5</spring_reference>
            <spring_stiffness>0.02</spring_stiffness>
          </dynamics>
        </axis>
        <physics>
          <ode>
            <cfm_damping>1</cfm_damping>
            <implicit_spring_damper>1</implicit_spring_damper>
            <limit>
              <cfm>0</cfm>
              <erp>0.2</erp>
            </limit>
          </ode>
        </physics>
      </joint>
      <link name='miro_head::ear_lh'>
        <inertial>
          <pose>-0.0437 0.0474 0.2773 0 -0 0</pose>
          <mass>0.056549</mass>
          <inertia>
            <ixx>3.393e-05</ixx>
            <ixy>0</ixy>
            <ixz>0</ixz>
            <iyy>3.393e-05</iyy>
            <iyz>0</iyz>
            <izz>3.393e-05</izz>
          </inertia>
        </inertial>
        <visual name='visual_ear_lh'>
          <pose>0 0 0 0 -0 0</pose>
          <geometry>
            <mesh>
              <uri>model://miro_model/meshes/ear_lh.dae</uri>
            </mesh>
          </geometry>
          <material>
            <script>
              <uri>file://media/materials/scripts/gazebo.material</uri>
              <name>Gazebo/Grey</name>
            </script>
          </material>
        </visual>
        <collision name='collision_ear_lh'>
          <pose>0 0 0 0 -0 0</pose>
          <geometry>
            <mesh>
              <uri>model://miro_model/meshes/ear_lh_collision.dae</uri>
            </mesh>
          </geometry>
          <surface>
            <friction>
              <ode>
                <mu>0.3</mu>
                <mu2>0.3</mu2>
              </ode>
              <torsional>
                <ode/>
              </torsional>
            </friction>
            <contact>
              <ode/>
            </contact>
            <bounce/>
          </surface>
          <max_contacts>10</max_contacts>
        </collision>
        <pose relative_to='miro_head::__model__'>0 0 0 0 -0 0</pose>
        <self_collide>0</self_collide>
        <enable_wind>0</enable_wind>
        <kinematic>0</kinematic>
      </link>
      <link name='miro_head::ear_rh'>
        <inertial>
          <pose>-0.0437 -0.0474 0.2773 0 -0 0</pose>
          <mass>0.056549</mass>
          <inertia>
            <ixx>3.393e-05</ixx>
            <ixy>0</ixy>
            <ixz>0</ixz>
            <iyy>3.393e-05</iyy>
            <iyz>0</iyz>
            <izz>3.393e-05</izz>
          </inertia>
        </inertial>
        <visual name='visual_ear_rh'>
          <pose>0 0 0 0 -0 0</pose>
          <geometry>
            <mesh>
              <uri>model://miro_model/meshes/ear_rh.dae</uri>
            </mesh>
          </geometry>
          <material>
            <script>
              <uri>file://media/materials/scripts/gazebo.material</uri>
              <name>Gazebo/Grey</name>
            </script>
          </material>
        </visual>
        <collision name='collision_ear_rh'>
          <pose>0 0 0 0 -0 0</pose>
          <geometry>
            <mesh>
              <uri>model://miro_model/meshes/ear_rh_collision.dae</uri>
            </mesh>
          </geometry>
          <surface>
            <friction>
              <ode>
                <mu>0.3</mu>
                <mu2>0.3</mu2>
              </ode>
              <torsional>
                <ode/>
              </torsional>
            </friction>
            <contact>
              <ode/>
            </contact>
            <bounce/>
          </surface>
          <max_contacts>10</max_contacts>
        </collision>
        <pose relative_to='miro_head::__model__'>0 0 0 0 -0 0</pose>
        <self_collide>0</self_collide>
        <enable_wind>0</enable_wind>
        <kinematic>0</kinematic>
      </link>
      <joint name='miro_head::head_ear_lh' type='revolute'>
        <pose>-0.0437 0.0474 0.2773 0 -0 0</pose>
        <parent>miro_head::head</parent>
        <child>miro_head::ear_lh</child>
        <axis>
          <xyz>-0.573 0.4344 0.6949</xyz>
          <limit>
            <lower>-1.57</lower>
            <upper>1.57</upper>
          </limit>
          <dynamics>
            <friction>0.01</friction>
            <damping>0.001</damping>
            <spring_reference>0</spring_reference>
            <spring_stiffness>0</spring_stiffness>
          </dynamics>
        </axis>
      </joint>
      <joint name='miro_head::head_ear_rh' type='revolute'>
        <pose>-0.0437 -0.0474 0.2773 0 -0 0</pose>
        <parent>miro_head::head</parent>
        <child>miro_head::ear_rh</child>
        <axis>
          <xyz>-0.573 -0.4344 0.6949</xyz>
          <limit>
            <lower>-1.57</lower>
            <upper>1.57</upper>
          </limit>
          <dynamics>
            <friction>0.01</friction>
            <damping>0.001</damping>
            <spring_reference>0</spring_reference>
            <spring_stiffness>0</spring_stiffness>
          </dynamics>
        </axis>
      </joint>
      <plugin name='miro_model' filename='libmiro_gazebo.so'/>
      <pose>0 0 0 0 -0 0</pose>
    </model>
    <model name='miro02'>
      <frame name='miro_body::__model__' attached_to='miro_body::body'>
        <pose relative_to='__model__'>0 0 0 0 -0 0</pose>
      </frame>
      <link name='miro_body::body'>
        <inertial>
          <pose>-0.06 0 0.05 0 -0 0</pose>
          <mass>1.5708</mass>
          <inertia>
            <ixx>0.00523599</ixx>
            <ixy>0</ixy>
            <ixz>0</ixz>
            <iyy>0.00523599</iyy>
            <iyz>0</iyz>
            <izz>0.00785398</izz>
          </inertia>
        </inertial>
        <visual name='visual_valance'>
          <pose>0 0 0 0 -0 0</pose>
          <geometry>
            <mesh>
              <uri>model://miro_model/meshes/valance.dae</uri>
            </mesh>
          </geometry>
          <material>
            <script>
              <uri>file://media/materials/scripts/gazebo.material</uri>
              <name>Gazebo/Grey</name>
            </script>
          </material>
        </visual>
        <collision name='collision_valance'>
          <pose>0 0 0 0 -0 0</pose>
          <geometry>
            <mesh>
              <uri>model://miro_model/meshes/valance_collision.dae</uri>
            </mesh>
          </geometry>
          <surface>
            <friction>
              <ode>
                <mu>0.1</mu>
                <mu2>0.1</mu2>
              </ode>
              <torsional>
                <ode/>
              </torsional>
            </friction>
            <contact>
              <ode/>
            </contact>
            <bounce/>
          </surface>
          <max_contacts>10</max_contacts>
        </collision>
        <visual name='visual_skirt_lh'>
          <pose>0 0 0 0 -0 0</pose>
          <geometry>
            <mesh>
              <uri>model://miro_model/meshes/skirt_lh.dae</uri>
            </mesh>
          </geometry>
          <material>
            <script>
              <uri>file://media/materials/scripts/gazebo.material</uri>
              <name>Gazebo/Grey</name>
            </script>
          </material>
        </visual>
        <visual name='visual_skirt_rh'>
          <pose>0 0 0 0 -0 0</pose>
          <geometry>
            <mesh>
              <uri>model://miro_model/meshes/skirt_rh.dae</uri>
            </mesh>
          </geometry>
          <material>
            <script>
              <uri>file://media/materials/scripts/gazebo.material</uri>
              <name>Gazebo/Grey</name>
            </script>
          </material>
        </visual>
        <visual name='visual_cliff_sensor_L_asm'>
          <pose>0 0 0 0 -0 0</pose>
          <geometry>
            <mesh>
              <uri>model://miro_model/meshes/cliff_sensor_L_asm.dae</uri>
            </mesh>
          </geometry>
          <material>
            <script>
              <uri>file://media/materials/scripts/gazebo.material</uri>
              <name>Gazebo/DarkGrey</name>
            </script>
          </material>
        </visual>
        <visual name='visual_cliff_sensor_R_asm'>
          <pose>0 0 0 0 -0 0</pose>
          <geometry>
            <mesh>
              <uri>model://miro_model/meshes/cliff_sensor_R_asm.dae</uri>
            </mesh>
          </geometry>
          <material>
            <script>
              <uri>file://media/materials/scripts/gazebo.material</uri>
              <name>Gazebo/DarkGrey</name>
            </script>
          </material>
        </visual>
        <visual name='visual_light_sensor_holder_asm_L'>
          <pose>0 0 0 0 -0 0</pose>
          <geometry>
            <mesh>
              <uri>model://miro_model/meshes/light_sensor_holder_asm_L.dae</uri>
            </mesh>
          </geometry>
          <material>
            <script>
              <uri>file://media/materials/scripts/gazebo.material</uri>
              <name>Gazebo/DarkGrey</name>
            </script>
          </material>
        </visual>
        <visual name='visual_light_sensor_holder_asm_R'>
          <pose>0 0 0 0 -0 0</pose>
          <geometry>
            <mesh>
              <uri>model://miro_model/meshes/light_sensor_holder_asm_R.dae</uri>
            </mesh>
          </geometry>
          <material>
            <script>
              <uri>file://media/materials/scripts/gazebo.material</uri>
              <name>Gazebo/DarkGrey</name>
            </script>
          </material>
        </visual>
        <visual name='visual_body_shell'>
          <pose>0 0 0 0 -0 0</pose>
          <geometry>
            <mesh>
              <uri>model://miro_model/meshes/body_shell.dae</uri>
            </mesh>
          </geometry>
          <material>
            <script>
              <uri>file://media/materials/scripts/gazebo.material</uri>
              <name>Gazebo/White</name>
            </script>
          </material>
        </visual>
        <collision name='collision_body_shell'>
          <pose>0 0 0 0 -0 0</pose>
          <geometry>
            <mesh>
              <uri>model://miro_model/meshes/body_shell_collision.dae</uri>
            </mesh>
          </geometry>
          <surface>
            <friction>
              <ode>
                <mu>0.1</mu>
                <mu2>0.1</mu2>
              </ode>
              <torsional>
                <ode/>
              </torsional>
            </friction>
            <contact>
              <ode/>
            </contact>
            <bounce/>
          </surface>
          <max_contacts>10</max_contacts>
        </collision>
        <visual name='visual_slider'>
          <pose>0 0 0 0 -0 0</pose>
          <geometry>
            <mesh>
              <uri>model://miro_model/meshes/slider.dae</uri>
            </mesh>
          </geometry>
          <material>
            <script>
              <uri>file://media/materials/scripts/gazebo.material</uri>
              <name>Gazebo/DarkGrey</name>
            </script>
          </material>
        </visual>
        <collision name='collision_slider'>
          <pose>-0.1075 0 0.0264 0 -0 0</pose>
          <geometry>
            <sphere>
              <radius>0.015</radius>
            </sphere>
          </geometry>
          <surface>
            <friction>
              <ode>
                <mu>0.01</mu>
                <mu2>0.01</mu2>
              </ode>
              <torsional>
                <ode/>
              </torsional>
            </friction>
            <contact>
              <ode/>
            </contact>
            <bounce/>
          </surface>
          <max_contacts>10</max_contacts>
        </collision>
        <sensor name='acc_body' type='imu'>
          <pose>0 0 0 0 -0 0</pose>
          <always_on>1</always_on>
          <update_rate>50</update_rate>
          <visualize>0</visualize>
          <imu/>
        </sensor>
        <sensor name='cliff_l' type='sonar'>
          <pose>0.062 0.055 0.085 0 -0.52 0</pose>
          <always_on>1</always_on>
          <update_rate>50</update_rate>
          <visualize>0</visualize>
          <sonar>
            <min>0</min>
            <max>0.5</max>
            <radius>0.025</radius>
          </sonar>
        </sensor>
        <sensor name='cliff_r' type='sonar'>
          <pose>0.062 -0.055 0.085 0 -0.52 0</pose>
          <always_on>1</always_on>
          <update_rate>50</update_rate>
          <visualize>0</visualize>
          <sonar>
            <min>0</min>
            <max>0.5</max>
            <radius>0.025</radius>
          </sonar>
        </sensor>
        <sensor name='lightfl' type='camera'>
          <pose>0.055 0.065 0.08 -0 -0.06 0.52</pose>
          <camera>
            <horizontal_fov>1.57</horizontal_fov>
            <image>
              <width>16</width>
              <height>12</height>
            </image>
            <clip>
              <near>0.01</near>
              <far>10</far>
            </clip>
          </camera>
          <always_on>1</always_on>
          <update_rate>5</update_rate>
          <visualize>0</visualize>
        </sensor>
        <sensor name='lightfr' type='camera'>
          <pose>0.055 -0.065 0.08 0 -0.06 -0.52</pose>
          <camera>
            <horizontal_fov>1.57</horizontal_fov>
            <image>
              <width>16</width>
              <height>12</height>
            </image>
            <clip>
              <near>0.01</near>
              <far>10</far>
            </clip>
          </camera>
          <always_on>1</always_on>
          <update_rate>5</update_rate>
          <visualize>0</visualize>
        </sensor>
        <sensor name='lightrl' type='camera'>
          <pose>-0.125 0.072 0.06 0 -0.26 2.61</pose>
          <camera>
            <horizontal_fov>1.57</horizontal_fov>
            <image>
              <width>16</width>
              <height>12</height>
            </image>
            <clip>
              <near>0.01</near>
              <far>10</far>
            </clip>
          </camera>
          <always_on>1</always_on>
          <update_rate>5</update_rate>
          <visualize>0</visualize>
        </sensor>
        <sensor name='lightrr' type='camera'>
          <pose>-0.125 -0.072 0.06 0 -0.26 -2.61</pose>
          <camera>
            <horizontal_fov>1.57</horizontal_fov>
            <image>
              <width>16</width>
              <height>12</height>
            </image>
            <clip>
              <near>0.01</near>
              <far>10</far>
            </clip>
          </camera>
          <always_on>1</always_on>
          <update_rate>5</update_rate>
          <visualize>0</visualize>
        </sensor>
        <pose relative_to='miro_body::__model__'>0 0 0 0 -0 0</pose>
        <self_collide>0</self_collide>
        <enable_wind>0</enable_wind>
        <kinematic>0</kinematic>
      </link>
      <link name='miro_body::wheel_lh'>
        <inertial>
          <pose>0.00063 0.07779 0.044838 0 -0 0</pose>
          <mass>0.134041</mass>
          <inertia>
            <ixx>0.00014298</ixx>
            <ixy>0</ixy>
            <ixz>0</ixz>
            <iyy>0.00014298</iyy>
            <iyz>0</iyz>
            <izz>0.00014298</izz>
          </inertia>
        </inertial>
        <visual name='visual_wheel_tyre_lh'>
          <pose>0 0 0 0 -0 0</pose>
          <geometry>
            <mesh>
              <uri>model://miro_model/meshes/wheel_tyre_lh.dae</uri>
            </mesh>
          </geometry>
          <material>
            <script>
              <uri>file://media/materials/scripts/gazebo.material</uri>
              <name>Gazebo/DarkGrey</name>
            </script>
          </material>
        </visual>
        <collision name='collision_wheel_tyre_lh'>
          <pose>0.00063 0.07779 0.044838 -1.5446 0 0</pose>
          <geometry>
            <cylinder>
              <radius>0.045</radius>
              <length>0.002</length>
            </cylinder>
          </geometry>
          <surface>
            <friction>
              <ode>
                <mu>1</mu>
                <mu2>1</mu2>
              </ode>
              <torsional>
                <ode/>
              </torsional>
            </friction>
            <contact>
              <ode/>
            </contact>
            <bounce/>
          </surface>
          <max_contacts>10</max_contacts>
        </collision>
        <visual name='visual_wheel_rim_lh'>
          <pose>0 0 0 0 -0 0</pose>
          <geometry>
            <mesh>
              <uri>model://miro_model/meshes/wheel_rim_lh.dae</uri>
            </mesh>
          </geometry>
          <material>
            <script>
              <uri>file://media/materials/scripts/gazebo.material</uri>
              <name>Gazebo/Grey</name>
            </script>
          </material>
        </visual>
        <pose relative_to='miro_body::__model__'>0 0 0 0 -0 0</pose>
        <self_collide>0</self_collide>
        <enable_wind>0</enable_wind>
        <kinematic>0</kinematic>
      </link>
      <link name='miro_body::wheel_rh'>
        <inertial>
          <pose>0.00063 -0.07779 0.044838 0 -0 0</pose>
          <mass>0.134041</mass>
          <inertia>
            <ixx>0.00014298</ixx>
            <ixy>0</ixy>
            <ixz>0</ixz>
            <iyy>0.00014298</iyy>
            <iyz>0</iyz>
            <izz>0.00014298</izz>
          </inertia>
        </inertial>
        <visual name='visual_wheel_tyre_rh'>
          <pose>0 0 0 0 -0 0</pose>
          <geometry>
            <mesh>
              <uri>model://miro_model/meshes/wheel_tyre_rh.dae</uri>
            </mesh>
          </geometry>
          <material>
            <script>
              <uri>file://media/materials/scripts/gazebo.material</uri>
              <name>Gazebo/DarkGrey</name>
            </script>
          </material>
        </visual>
        <collision name='collision_wheel_tyre_rh'>
          <pose>0.00063 -0.07779 0.044838 1.5446 -0 0</pose>
          <geometry>
            <cylinder>
              <radius>0.045</radius>
              <length>0.002</length>
            </cylinder>
          </geometry>
          <surface>
            <friction>
              <ode>
                <mu>1</mu>
                <mu2>1</mu2>
              </ode>
              <torsional>
                <ode/>
              </torsional>
            </friction>
            <contact>
              <ode/>
            </contact>
            <bounce/>
          </surface>
          <max_contacts>10</max_contacts>
        </collision>
        <visual name='visual_wheel_rim_rh'>
          <pose>0 0 0 0 -0 0</pose>
          <geometry>
            <mesh>
              <uri>model://miro_model/meshes/wheel_rim_rh.dae</uri>
            </mesh>
          </geometry>
          <material>
            <script>
              <uri>file://media/materials/scripts/gazebo.material</uri>
              <name>Gazebo/Grey</name>
            </script>
          </material>
        </visual>
        <pose relative_to='miro_body::__model__'>0 0 0 0 -0 0</pose>
        <self_collide>0</self_collide>
        <enable_wind>0</enable_wind>
        <kinematic>0</kinematic>
      </link>
      <joint name='miro_body::body_wheel_lh' type='revolute'>
        <pose>0.00063 0.07779 0.044838 0 -0 0</pose>
        <parent>miro_body::body</parent>
        <child>miro_body::wheel_lh</child>
        <axis>
          <xyz>0 0.999657 0.026185</xyz>
          <dynamics>
            <friction>0.1</friction>
            <damping>0.1</damping>
            <spring_reference>0</spring_reference>
            <spring_stiffness>0</spring_stiffness>
          </dynamics>
          <limit>
            <lower>-1e+16</lower>
            <upper>1e+16</upper>
          </limit>
        </axis>
      </joint>
      <joint name='miro_body::body_wheel_rh' type='revolute'>
        <pose>0.00063 -0.07779 0.044838 0 -0 0</pose>
        <parent>miro_body::body</parent>
        <child>miro_body::wheel_rh</child>
        <axis>
          <xyz>0 0.999657 -0.026185</xyz>
          <dynamics>
            <friction>0.1</friction>
            <damping>0.1</damping>
            <spring_reference>0</spring_reference>
            <spring_stiffness>0</spring_stiffness>
          </dynamics>
          <limit>
            <lower>-1e+16</lower>
            <upper>1e+16</upper>
          </limit>
        </axis>
      </joint>
      <frame name='miro_tail::__model__' attached_to='miro_tail::tail_gmbl'>
        <pose relative_to='__model__'>0 0 0 0 -0 0</pose>
      </frame>
      <link name='miro_tail::tail_gmbl'>
        <inertial>
          <pose>-0.143 0 0.085 0 -0 0</pose>
          <mass>0.056549</mass>
          <inertia>
            <ixx>3.393e-05</ixx>
            <ixy>0</ixy>
            <ixz>0</ixz>
            <iyy>3.393e-05</iyy>
            <iyz>0</iyz>
            <izz>3.393e-05</izz>
          </inertia>
        </inertial>
        <pose relative_to='miro_tail::__model__'>0 0 0 0 -0 0</pose>
        <self_collide>0</self_collide>
        <enable_wind>0</enable_wind>
        <kinematic>0</kinematic>
      </link>
      <joint name='miro_tail::body_tail_gmbl' type='revolute'>
        <pose>-0.143 0 0.085 0 -0 0</pose>
        <parent>miro_body::body</parent>
        <child>miro_tail::tail_gmbl</child>
        <axis>
          <xyz>0 1 0</xyz>
          <limit>
            <lower>-1.57</lower>
            <upper>1.57</upper>
          </limit>
          <dynamics>
            <friction>0.01</friction>
            <damping>0.02</damping>
            <spring_reference>0</spring_reference>
            <spring_stiffness>0</spring_stiffness>
          </dynamics>
        </axis>
      </joint>
      <link name='miro_tail::tail'>
        <inertial>
          <pose>-0.143 0 0.085 0 -0 0</pose>
          <mass>0.056549</mass>
          <inertia>
            <ixx>3.393e-05</ixx>
            <ixy>0</ixy>
            <ixz>0</ixz>
            <iyy>3.393e-05</iyy>
            <iyz>0</iyz>
            <izz>3.393e-05</izz>
          </inertia>
        </inertial>
        <visual name='visual_tail'>
          <pose>0 0 0 0 -0 0</pose>
          <geometry>
            <mesh>
              <uri>model://miro_model/meshes/tail.dae</uri>
            </mesh>
          </geometry>
          <material>
            <script>
              <uri>file://media/materials/scripts/gazebo.material</uri>
              <name>Gazebo/Grey</name>
            </script>
          </material>
        </visual>
        <collision name='collision_tail'>
          <pose>0 0 0 0 -0 0</pose>
          <geometry>
            <mesh>
              <uri>model://miro_model/meshes/tail_collision.dae</uri>
            </mesh>
          </geometry>
          <surface>
            <friction>
              <ode>
                <mu>0.1</mu>
                <mu2>0.1</mu2>
              </ode>
              <torsional>
                <ode/>
              </torsional>
            </friction>
            <contact>
              <ode/>
            </contact>
            <bounce/>
          </surface>
          <max_contacts>10</max_contacts>
        </collision>
        <pose relative_to='miro_tail::__model__'>0 0 0 0 -0 0</pose>
        <self_collide>0</self_collide>
        <enable_wind>0</enable_wind>
        <kinematic>0</kinematic>
      </link>
      <joint name='miro_tail::tail_gmbl_tail' type='revolute'>
        <pose>-0.143 0 0.085 0 -0 0</pose>
        <parent>miro_tail::tail_gmbl</parent>
        <child>miro_tail::tail</child>
        <axis>
          <xyz>0 0 1</xyz>
          <limit>
            <lower>-1.57</lower>
            <upper>1.57</upper>
          </limit>
          <dynamics>
            <friction>0.01</friction>
            <damping>0.02</damping>
            <spring_reference>0</spring_reference>
            <spring_stiffness>0</spring_stiffness>
          </dynamics>
        </axis>
      </joint>
      <joint name='body_neck' type='revolute'>
        <pose>-0.002 0 0.081 0 -0 0</pose>
        <parent>miro_body::body</parent>
        <child>miro_neck::neck</child>
        <axis>
          <xyz>0 1 0</xyz>
          <limit>
            <lower>0</lower>
            <upper>1.57</upper>
          </limit>
          <dynamics>
            <spring_stiffness>0.4</spring_stiffness>
            <spring_reference>0</spring_reference>
            <friction>0.01</friction>
            <damping>0.1</damping>
          </dynamics>
        </axis>
      </joint>
      <frame name='miro_neck::__model__' attached_to='miro_neck::neck'>
        <pose relative_to='__model__'>0 0 0 0 -0 0</pose>
      </frame>
      <link name='miro_neck::neck'>
        <inertial>
          <pose>-0.002 0 0.141 0 -0 0</pose>
          <mass>0.075398</mass>
          <inertia>
            <ixx>9.802e-05</ixx>
            <ixy>0</ixy>
            <ixz>0</ixz>
            <iyy>9.802e-05</iyy>
            <iyz>0</iyz>
            <izz>1.508e-05</izz>
          </inertia>
        </inertial>
        <pose relative_to='miro_neck::__model__'>0 0 0 0 -0 0</pose>
        <self_collide>0</self_collide>
        <enable_wind>0</enable_wind>
        <kinematic>0</kinematic>
      </link>
      <joint name='neck_gmbl' type='revolute'>
        <pose>-0.002 0 0.201 0 -0 0</pose>
        <parent>miro_neck::neck</parent>
        <child>miro_gmbl::gmbl</child>
        <axis>
          <xyz>0 0 1</xyz>
          <limit>
            <lower>-1.57</lower>
            <upper>1.57</upper>
          </limit>
          <dynamics>
            <friction>0.01</friction>
            <damping>0.1</damping>
            <spring_reference>0</spring_reference>
            <spring_stiffness>0</spring_stiffness>
          </dynamics>
        </axis>
      </joint>
      <frame name='miro_gmbl::__model__' attached_to='miro_gmbl::gmbl'>
        <pose relative_to='__model__'>0 0 0 0 -0 0</pose>
      </frame>
      <link name='miro_gmbl::gmbl'>
        <inertial>
          <pose>-0.002 0 0.171 0 -0 0</pose>
          <mass>0.03927</mass>
          <inertia>
            <ixx>2.487e-05</ixx>
            <ixy>0</ixy>
            <ixz>0</ixz>
            <iyy>2.487e-05</iyy>
            <iyz>0</iyz>
            <izz>4.909e-05</izz>
          </inertia>
        </inertial>
        <visual name='visual_collar'>
          <pose>0 0 0 0 -0 0</pose>
          <geometry>
            <mesh>
              <uri>model://miro_model/meshes/collar.dae</uri>
            </mesh>
          </geometry>
          <material>
            <script>
              <uri>file://media/materials/scripts/gazebo.material</uri>
              <name>Gazebo/Red</name>
            </script>
          </material>
        </visual>
        <pose relative_to='miro_gmbl::__model__'>0 0 0 0 -0 0</pose>
        <self_collide>0</self_collide>
        <enable_wind>0</enable_wind>
        <kinematic>0</kinematic>
      </link>
      <joint name='gmbl_head' type='revolute'>
        <pose>-0.002 0 0.201 0 -0 0</pose>
        <parent>miro_gmbl::gmbl</parent>
        <child>miro_head::head</child>
        <axis>
          <xyz>0 1 0</xyz>
          <limit>
            <lower>-1.57</lower>
            <upper>1.57</upper>
          </limit>
          <dynamics>
            <spring_stiffness>0.1</spring_stiffness>
            <spring_reference>-0.5</spring_reference>
            <friction>0.01</friction>
            <damping>0.1</damping>
          </dynamics>
        </axis>
      </joint>
      <frame name='miro_head::__model__' attached_to='miro_head::head'>
        <pose relative_to='__model__'>0 0 0 0 -0 0</pose>
      </frame>
      <link name='miro_head::head'>
        <inertial>
          <pose>-0.002 0 0.221 0 -0 0</pose>
          <mass>0.261799</mass>
          <inertia>
            <ixx>0.00043633</ixx>
            <ixy>0</ixy>
            <ixz>0</ixz>
            <iyy>0.00043633</iyy>
            <iyz>0</iyz>
            <izz>0.00043633</izz>
          </inertia>
        </inertial>
        <visual name='visual_head_lower'>
          <pose>0 0 0 0 -0 0</pose>
          <geometry>
            <mesh>
              <uri>model://miro_model/meshes/head_lower.dae</uri>
            </mesh>
          </geometry>
          <material>
            <script>
              <uri>file://media/materials/scripts/gazebo.material</uri>
              <name>Gazebo/White</name>
            </script>
          </material>
        </visual>
        <collision name='collision_head_lower'>
          <pose>0 0 0 0 -0 0</pose>
          <geometry>
            <mesh>
              <uri>model://miro_model/meshes/head_lower_collision.dae</uri>
            </mesh>
          </geometry>
          <surface>
            <friction>
              <ode>
                <mu>0.1</mu>
                <mu2>0.1</mu2>
              </ode>
              <torsional>
                <ode/>
              </torsional>
            </friction>
            <contact>
              <ode/>
            </contact>
            <bounce/>
          </surface>
          <max_contacts>10</max_contacts>
        </collision>
        <visual name='visual_head_upper'>
          <pose>0 0 0 0 -0 0</pose>
          <geometry>
            <mesh>
              <uri>model://miro_model/meshes/head_upper.dae</uri>
            </mesh>
          </geometry>
          <material>
            <script>
              <uri>file://media/materials/scripts/gazebo.material</uri>
              <name>Gazebo/White</name>
            </script>
          </material>
        </visual>
        <collision name='collision_head_upper'>
          <pose>0 0 0 0 -0 0</pose>
          <geometry>
            <mesh>
              <uri>model://miro_model/meshes/head_upper_collision.dae</uri>
            </mesh>
          </geometry>
          <surface>
            <friction>
              <ode>
                <mu>0.1</mu>
                <mu2>0.1</mu2>
              </ode>
              <torsional>
                <ode/>
              </torsional>
            </friction>
            <contact>
              <ode/>
            </contact>
            <bounce/>
          </surface>
          <max_contacts>10</max_contacts>
        </collision>
        <visual name='visual_eyelid_lower_lh'>
          <pose>0 0 0 0 -0 0</pose>
          <geometry>
            <mesh>
              <uri>model://miro_model/meshes/eyelid_lower_lh.dae</uri>
            </mesh>
          </geometry>
          <material>
            <script>
              <uri>file://media/materials/scripts/gazebo.material</uri>
              <name>Gazebo/White</name>
            </script>
          </material>
        </visual>
        <visual name='visual_eyelid_lower_rh'>
          <pose>0 0 0 0 -0 0</pose>
          <geometry>
            <mesh>
              <uri>model://miro_model/meshes/eyelid_lower_rh.dae</uri>
            </mesh>
          </geometry>
          <material>
            <script>
              <uri>file://media/materials/scripts/gazebo.material</uri>
              <name>Gazebo/White</name>
            </script>
          </material>
        </visual>
        <visual name='visual_nose'>
          <pose>0 0 0 0 -0 0</pose>
          <geometry>
            <mesh>
              <uri>model://miro_model/meshes/nose.dae</uri>
            </mesh>
          </geometry>
          <material>
            <script>
              <uri>file://media/materials/scripts/gazebo.material</uri>
              <name>Gazebo/Grey</name>
            </script>
          </material>
        </visual>
        <collision name='collision_nose'>
          <pose>0 0 0 0 -0 0</pose>
          <geometry>
            <mesh>
              <uri>model://miro_model/meshes/nose_collision.dae</uri>
            </mesh>
          </geometry>
          <surface>
            <friction>
              <ode>
                <mu>0.3</mu>
                <mu2>0.3</mu2>
              </ode>
              <torsional>
                <ode/>
              </torsional>
            </friction>
            <contact>
              <ode/>
            </contact>
            <bounce/>
          </surface>
          <max_contacts>10</max_contacts>
        </collision>
        <visual name='visual_1'>
          <pose>0.029 0.033 0.252 0 -0 0</pose>
          <geometry>
            <sphere>
              <radius>0.018</radius>
            </sphere>
          </geometry>
          <material>
            <script>
              <uri>file://media/materials/scripts/gazebo.material</uri>
              <name>Gazebo/White</name>
            </script>
          </material>
        </visual>
        <visual name='visual_2'>
          <pose>0.0315 0.036 0.254 0 -0 0</pose>
          <geometry>
            <sphere>
              <radius>0.015</radius>
            </sphere>
          </geometry>
          <material>
            <script>
              <uri>file://media/materials/scripts/gazebo.material</uri>
              <name>Gazebo/DarkGrey</name>
            </script>
          </material>
        </visual>
        <visual name='visual_3'>
          <pose>0.029 -0.033 0.252 0 -0 0</pose>
          <geometry>
            <sphere>
              <radius>0.018</radius>
            </sphere>
          </geometry>
          <material>
            <script>
              <uri>file://media/materials/scripts/gazebo.material</uri>
              <name>Gazebo/White</name>
            </script>
          </material>
        </visual>
        <visual name='visual_4'>
          <pose>0.0315 -0.036 0.254 0 -0 0</pose>
          <geometry>
            <sphere>
              <radius>0.015</radius>
            </sphere>
          </geometry>
          <material>
            <script>
              <uri>file://media/materials/scripts/gazebo.material</uri>
              <name>Gazebo/DarkGrey</name>
            </script>
          </material>
        </visual>
        <sensor name='eye_l' type='wideanglecamera'>
          <pose>0.0377 0.0431 0.2595 -0.4262 -0.6816 0.6244</pose>
          <camera>
            <horizontal_fov>2.0944</horizontal_fov>
            <image>
              <width>1280</width>
              <height>720</height>
            </image>
            <clip>
              <near>0.006</near>
              <far>100</far>
            </clip>
            <lens>
              <type>custom</type>
              <scale_to_hfov>1</scale_to_hfov>
              <custom_function>
                <c1>2</c1>
                <c2>1.25</c2>
                <c3>0</c3>
                <f>1</f>
                <fun>sin</fun>
              </custom_function>
            </lens>
          </camera>
          <always_on>1</always_on>
          <update_rate>10</update_rate>
          <visualize>0</visualize>
        </sensor>
        <sensor name='eye_r' type='wideanglecamera'>
          <pose>0.0377 -0.0431 0.2595 0.4261 -0.6816 -0.6244</pose>
          <camera>
            <horizontal_fov>2.0944</horizontal_fov>
            <image>
              <width>1280</width>
              <height>720</height>
            </image>
            <clip>
              <near>0.006</near>
              <far>100</far>
            </clip>
            <lens>
              <type>custom</type>
              <scale_to_hfov>1</scale_to_hfov>
              <custom_function>
                <c1>2</c1>
                <c2>1.25</c2>
                <c3>0</c3>
                <f>1</f>
                <fun>sin</fun>
              </custom_function>
            </lens>
          </camera>
          <always_on>1</always_on>
          <update_rate>10</update_rate>
          <visualize>0</visualize>
        </sensor>
        <sensor name='eye_l_narrow' type='camera'>
          <pose>0.0377 0.0431 0.2595 -0.4262 -0.6816 0.6244</pose>
          <camera>
            <horizontal_fov>2.0944</horizontal_fov>
            <image>
              <width>1280</width>
              <height>720</height>
            </image>
            <clip>
              <near>0.006</near>
              <far>100</far>
            </clip>
          </camera>
          <always_on>1</always_on>
          <update_rate>10</update_rate>
          <visualize>0</visualize>
        </sensor>
        <sensor name='eye_r_narrow' type='camera'>
          <pose>0.0377 -0.0431 0.2595 0.4261 -0.6816 -0.6244</pose>
          <camera>
            <horizontal_fov>2.0944</horizontal_fov>
            <image>
              <width>1280</width>
              <height>720</height>
            </image>
            <clip>
              <near>0.006</near>
              <far>100</far>
            </clip>
          </camera>
          <always_on>1</always_on>
          <update_rate>10</update_rate>
          <visualize>0</visualize>
        </sensor>
        <sensor name='gaze' type='camera'>
          <pose>0.0577 0 0.2795 0 -0.785398 0</pose>
          <camera>
            <horizontal_fov>1</horizontal_fov>
            <image>
              <width>1280</width>
              <height>720</height>
            </image>
            <clip>
              <near>0.001</near>
              <far>100</far>
            </clip>
          </camera>
          <always_on>1</always_on>
          <update_rate>10</update_rate>
          <visualize>0</visualize>
        </sensor>
        <sensor name='overhead' type='camera'>
          <pose>0 0 1 0 1.22 0</pose>
          <camera>
            <horizontal_fov>1.0472</horizontal_fov>
            <image>
              <width>1280</width>
              <height>720</height>
            </image>
            <clip>
              <near>0.01</near>
              <far>2</far>
            </clip>
          </camera>
          <always_on>1</always_on>
          <update_rate>10</update_rate>
          <visualize>0</visualize>
        </sensor>
        <sensor name='acc_head' type='imu'>
          <pose>0 0 0 0 -0 0</pose>
          <always_on>1</always_on>
          <update_rate>50</update_rate>
          <visualize>0</visualize>
          <imu/>
        </sensor>
        <sensor name='sonar' type='sonar'>
          <pose>0.1 0 0.235 3.14159 -1.57079 3.14159</pose>
          <always_on>1</always_on>
          <update_rate>50</update_rate>
          <visualize>0</visualize>
          <sonar>
            <min>0</min>
            <max>1</max>
            <radius>0.309</radius>
          </sonar>
        </sensor>
        <pose relative_to='miro_head::__model__'>0 0 0 0 -0 0</pose>
        <self_collide>0</self_collide>
        <enable_wind>0</enable_wind>
        <kinematic>0</kinematic>
      </link>
      <link name='miro_head::eyelid_lh'>
        <inertial>
          <pose>0.029 0.032 0.252 0 -0 0</pose>
          <mass>0.016755</mass>
          <inertia>
            <ixx>4.47e-06</ixx>
            <ixy>0</ixy>
            <ixz>0</ixz>
            <iyy>4.47e-06</iyy>
            <iyz>0</iyz>
            <izz>4.47e-06</izz>
          </inertia>
        </inertial>
        <visual name='visual_eyelid_lh'>
          <pose>0 0 0 0 -0 0</pose>
          <geometry>
            <mesh>
              <uri>model://miro_model/meshes/eyelid_lh.dae</uri>
            </mesh>
          </geometry>
          <material>
            <script>
              <uri>file://media/materials/scripts/gazebo.material</uri>
              <name>Gazebo/White</name>
            </script>
          </material>
        </visual>
        <pose relative_to='miro_head::__model__'>0 0 0 0 -0 0</pose>
        <self_collide>0</self_collide>
        <enable_wind>0</enable_wind>
        <kinematic>0</kinematic>
      </link>
      <link name='miro_head::eyelid_rh'>
        <inertial>
          <pose>0.029 -0.032 0.252 0 -0 0</pose>
          <mass>0.016755</mass>
          <inertia>
            <ixx>4.47e-06</ixx>
            <ixy>0</ixy>
            <ixz>0</ixz>
            <iyy>4.47e-06</iyy>
            <iyz>0</iyz>
            <izz>4.47e-06</izz>
          </inertia>
        </inertial>
        <visual name='visual_eyelid_rh'>
          <pose>0 0 0 0 -0 0</pose>
          <geometry>
            <mesh>
              <uri>model://miro_model/meshes/eyelid_rh.dae</uri>
            </mesh>
          </geometry>
          <material>
            <script>
              <uri>file://media/materials/scripts/gazebo.material</uri>
              <name>Gazebo/White</name>
            </script>
          </material>
        </visual>
        <pose relative_to='miro_head::__model__'>0 0 0 0 -0 0</pose>
        <self_collide>0</self_collide>
        <enable_wind>0</enable_wind>
        <kinematic>0</kinematic>
      </link>
      <joint name='miro_head::head_eyelid_lh' type='revolute'>
        <pose>0.029 0.032 0.252 0 -0 0</pose>
        <parent>miro_head::head</parent>
        <child>miro_head::eyelid_lh</child>
        <axis>
          <xyz>-0.675 0.675 -0.2978</xyz>
          <limit>
            <lower>-1.57</lower>
            <upper>1.57</upper>
          </limit>
          <dynamics>
            <friction>0.1</friction>
            <damping>0.1</damping>
            <spring_reference>-0.5</spring_reference>
            <spring_stiffness>0.02</spring_stiffness>
          </dynamics>
        </axis>
        <physics>
          <ode>
            <cfm_damping>1</cfm_damping>
            <implicit_spring_damper>1</implicit_spring_damper>
            <limit>
              <cfm>0</cfm>
              <erp>0.2</erp>
            </limit>
          </ode>
        </physics>
      </joint>
      <joint name='miro_head::head_eyelid_rh' type='revolute'>
        <pose>0.029 -0.032 0.252 0 -0 0</pose>
        <parent>miro_head::head</parent>
        <child>miro_head::eyelid_rh</child>
        <axis>
          <xyz>0.675 0.675 0.2978</xyz>
          <limit>
            <lower>-1.57</lower>
            <upper>1.57</upper>
          </limit>
          <dynamics>
            <friction>0.1</friction>
            <damping>0.1</damping>
            <spring_reference>-0.5</spring_reference>
            <spring_stiffness>0.02</spring_stiffness>
          </dynamics>
        </axis>
        <physics>
          <ode>
            <cfm_damping>1</cfm_damping>
            <implicit_spring_damper>1</implicit_spring_damper>
            <limit>
              <cfm>0</cfm>
              <erp>0.2</erp>
            </limit>
          </ode>
        </physics>
      </joint>
      <link name='miro_head::ear_lh'>
        <inertial>
          <pose>-0.0437 0.0474 0.2773 0 -0 0</pose>
          <mass>0.056549</mass>
          <inertia>
            <ixx>3.393e-05</ixx>
            <ixy>0</ixy>
            <ixz>0</ixz>
            <iyy>3.393e-05</iyy>
            <iyz>0</iyz>
            <izz>3.393e-05</izz>
          </inertia>
        </inertial>
        <visual name='visual_ear_lh'>
          <pose>0 0 0 0 -0 0</pose>
          <geometry>
            <mesh>
              <uri>model://miro_model/meshes/ear_lh.dae</uri>
            </mesh>
          </geometry>
          <material>
            <script>
              <uri>file://media/materials/scripts/gazebo.material</uri>
              <name>Gazebo/Grey</name>
            </script>
          </material>
        </visual>
        <collision name='collision_ear_lh'>
          <pose>0 0 0 0 -0 0</pose>
          <geometry>
            <mesh>
              <uri>model://miro_model/meshes/ear_lh_collision.dae</uri>
            </mesh>
          </geometry>
          <surface>
            <friction>
              <ode>
                <mu>0.3</mu>
                <mu2>0.3</mu2>
              </ode>
              <torsional>
                <ode/>
              </torsional>
            </friction>
            <contact>
              <ode/>
            </contact>
            <bounce/>
          </surface>
          <max_contacts>10</max_contacts>
        </collision>
        <pose relative_to='miro_head::__model__'>0 0 0 0 -0 0</pose>
        <self_collide>0</self_collide>
        <enable_wind>0</enable_wind>
        <kinematic>0</kinematic>
      </link>
      <link name='miro_head::ear_rh'>
        <inertial>
          <pose>-0.0437 -0.0474 0.2773 0 -0 0</pose>
          <mass>0.056549</mass>
          <inertia>
            <ixx>3.393e-05</ixx>
            <ixy>0</ixy>
            <ixz>0</ixz>
            <iyy>3.393e-05</iyy>
            <iyz>0</iyz>
            <izz>3.393e-05</izz>
          </inertia>
        </inertial>
        <visual name='visual_ear_rh'>
          <pose>0 0 0 0 -0 0</pose>
          <geometry>
            <mesh>
              <uri>model://miro_model/meshes/ear_rh.dae</uri>
            </mesh>
          </geometry>
          <material>
            <script>
              <uri>file://media/materials/scripts/gazebo.material</uri>
              <name>Gazebo/Grey</name>
            </script>
          </material>
        </visual>
        <collision name='collision_ear_rh'>
          <pose>0 0 0 0 -0 0</pose>
          <geometry>
            <mesh>
              <uri>model://miro_model/meshes/ear_rh_collision.dae</uri>
            </mesh>
          </geometry>
          <surface>
            <friction>
              <ode>
                <mu>0.3</mu>
                <mu2>0.3</mu2>
              </ode>
              <torsional>
                <ode/>
              </torsional>
            </friction>
            <contact>
              <ode/>
            </contact>
            <bounce/>
          </surface>
          <max_contacts>10</max_contacts>
        </collision>
        <pose relative_to='miro_head::__model__'>0 0 0 0 -0 0</pose>
        <self_collide>0</self_collide>
        <enable_wind>0</enable_wind>
        <kinematic>0</kinematic>
      </link>
      <joint name='miro_head::head_ear_lh' type='revolute'>
        <pose>-0.0437 0.0474 0.2773 0 -0 0</pose>
        <parent>miro_head::head</parent>
        <child>miro_head::ear_lh</child>
        <axis>
          <xyz>-0.573 0.4344 0.6949</xyz>
          <limit>
            <lower>-1.57</lower>
            <upper>1.57</upper>
          </limit>
          <dynamics>
            <friction>0.01</friction>
            <damping>0.001</damping>
            <spring_reference>0</spring_reference>
            <spring_stiffness>0</spring_stiffness>
          </dynamics>
        </axis>
      </joint>
      <joint name='miro_head::head_ear_rh' type='revolute'>
        <pose>-0.0437 -0.0474 0.2773 0 -0 0</pose>
        <parent>miro_head::head</parent>
        <child>miro_head::ear_rh</child>
        <axis>
          <xyz>-0.573 -0.4344 0.6949</xyz>
          <limit>
            <lower>-1.57</lower>
            <upper>1.57</upper>
          </limit>
          <dynamics>
            <friction>0.01</friction>
            <damping>0.001</damping>
            <spring_reference>0</spring_reference>
            <spring_stiffness>0</spring_stiffness>
          </dynamics>
        </axis>
      </joint>
      <plugin name='miro_model' filename='libmiro_gazebo.so'/>
      <pose>1.57977 1.54101 0.000364 -3e-05 -0.108206 1.53043</pose>
    </model>
  </world>
</sdf>
