<sdf version='1.7'>
  <world name='default'>
    <light name='sun' type='directional'>
      <cast_shadows>1</cast_shadows>
      <pose>0 0 10 0 -0 0</pose>
      <diffuse>0.8 0.8 0.8 1</diffuse>
      <specular>0.2 0.2 0.2 1</specular>
      <attenuation>
        <range>1000</range>
        <constant>0.9</constant>
        <linear>0.01</linear>
        <quadratic>0.001</quadratic>
      </attenuation>
      <direction>-0.5 0.1 -0.9</direction>
      <spot>
        <inner_angle>0</inner_angle>
        <outer_angle>0</outer_angle>
        <falloff>0</falloff>
      </spot>
    </light>
    <model name='ground_plane'>
      <static>1</static>
      <link name='link'>
        <collision name='collision'>
          <geometry>
            <plane>
              <normal>0 0 1</normal>
              <size>100 100</size>
            </plane>
          </geometry>
          <surface>
            <contact>
              <collide_bitmask>65535</collide_bitmask>
              <ode/>
            </contact>
            <friction>
              <ode>
                <mu>100</mu>
                <mu2>50</mu2>
              </ode>
              <torsional>
                <ode/>
              </torsional>
            </friction>
            <bounce/>
          </surface>
          <max_contacts>10</max_contacts>
        </collision>
        <visual name='visual'>
          <cast_shadows>0</cast_shadows>
          <geometry>
            <plane>
              <normal>0 0 1</normal>
              <size>100 100</size>
            </plane>
          </geometry>
          <material>
            <script>
              <uri>file://media/materials/scripts/gazebo.material</uri>
              <name>Gazebo/Grey</name>
            </script>
          </material>
        </visual>
        <self_collide>0</self_collide>
        <enable_wind>0</enable_wind>
        <kinematic>0</kinematic>
      </link>
    </model>
    <gravity>0 0 -9.8</gravity>
    <magnetic_field>6e-06 2.3e-05 -4.2e-05</magnetic_field>
    <atmosphere type='adiabatic'/>
    <physics type='ode'>
      <max_step_size>0.001</max_step_size>
      <real_time_factor>1</real_time_factor>
      <real_time_update_rate>1000</real_time_update_rate>
    </physics>
    <scene>
      <ambient>0.4 0.4 0.4 1</ambient>
      <background>0.7 0.7 0.7 1</background>
      <shadows>1</shadows>
    </scene>
    <wind/>
    <spherical_coordinates>
      <surface_model>EARTH_WGS84</surface_model>
      <latitude_deg>0</latitude_deg>
      <longitude_deg>0</longitude_deg>
      <elevation>0</elevation>
      <heading_deg>0</heading_deg>
    </spherical_coordinates>
    <state world_name='default'>
      <sim_time>436 685000000</sim_time>
      <real_time>67 639224539</real_time>
      <wall_time>1746994605 233812040</wall_time>
      <iterations>62539</iterations>
      <model name='ground_plane'>
        <pose>0 0 0 0 -0 0</pose>
        <scale>1 1 1</scale>
        <link name='link'>
          <pose>0 0 0 0 -0 0</pose>
          <velocity>0 0 0 0 -0 0</velocity>
          <acceleration>0 0 0 0 -0 0</acceleration>
          <wrench>0 0 0 0 -0 0</wrench>
        </link>
      </model>
      <model name='miro01'>
        <pose>-0.008693 0.120191 0.000364 -3.1e-05 -0.108204 1.56963</pose>
        <scale>1 1 1</scale>
        <link name='miro_body::body'>
          <pose>-0.008693 0.120191 0.000364 -3.1e-05 -0.108204 1.56963</pose>
          <velocity>0.002201 1e-06 -0.000154 -0.001567 -0.0593 0.003402</velocity>
          <acceleration>-0.650633 -0.012666 -0.084787 0.908564 0.854069 1.05082</acceleration>
          <wrench>-1.02201 -0.019895 -0.133183 0 -0 0</wrench>
        </link>
        <link name='miro_body::wheel_lh'>
          <pose>-0.008685 0.11878 0.000266 -0.000238 -0.075157 1.57051</pose>
          <velocity>3.6e-05 5.6e-05 -0.002797 -0.001405 -0.02748 0.003429</velocity>
          <acceleration>-2.40372 -0.149538 -9.71112 -1.38885 0.725937 2.09792</acceleration>
          <wrench>-0.322197 -0.020044 -1.30169 0 -0 0</wrench>
        </link>
        <link name='miro_body::wheel_rh'>
          <pose>-0.008707 0.118814 0.00027 0.000208 -0.075946 1.56877</pose>
          <velocity>4.2e-05 -0.000235 0.002577 -0.005923 -0.026924 0.003095</velocity>
          <acceleration>-2.39812 0.014214 9.38404 -2.65471 -0.852691 -1.52048</acceleration>
          <wrench>-0.321447 0.001905 1.25785 0 -0 0</wrench>
        </link>
        <link name='miro_gmbl::gmbl'>
          <pose>-0.008749 0.074076 0.00778 -1e-05 0.476526 1.56963</pose>
          <velocity>-0.000729 6.2e-05 -7.3e-05 -0.00101 -0.020036 0.00885</velocity>
          <acceleration>-8.68667 0.112846 -0.184126 1.84153 0.801475 1.6364</acceleration>
          <wrench>-0.341126 0.004431 -0.007231 0 -0 0</wrench>
        </link>
        <link name='miro_head::ear_lh'>
          <pose>-0.030641 0.090089 -2.8e-05 0.043908 0.397761 1.43123</pose>
          <velocity>-0.013163 0.001134 0.000617 0.001945 0.04127 -0.025989</velocity>
          <acceleration>0.371333 2.55647 3.69954 0.902821 0.329187 1.4371</acceleration>
          <wrench>0.020999 0.144566 0.209205 0 -0 0</wrench>
        </link>
        <link name='miro_head::ear_rh'>
          <pose>0.012727 0.089673 0.000109 -0.042831 0.399281 1.70511</pose>
          <velocity>-0.013068 1.1e-05 -0.001164 0.001945 0.040739 -0.025923</velocity>
          <acceleration>0.266907 -2.67904 -4.03423 1.01508 -0.624785 1.34248</acceleration>
          <wrench>0.015093 -0.151497 -0.228132 0 -0 0</wrench>
        </link>
        <link name='miro_head::eyelid_lh'>
          <pose>-0.075299 0.134264 -0.021374 0.288446 0.199439 1.6498</pose>
          <velocity>-0.012198 0.001703 0.002663 -0.000736 0.038454 -0.026013</velocity>
          <acceleration>-1.20311 1.77421 2.47915 1.95584 1.04126 1.14261</acceleration>
          <wrench>-0.020158 0.029727 0.041538 0 -0 0</wrench>
        </link>
        <link name='miro_head::eyelid_rh'>
          <pose>0.089164 0.162583 -0.022789 -0.406397 0.072311 1.4807</pose>
          <velocity>-0.011513 -0.001306 -0.004138 0.004513 0.038424 -0.025869</velocity>
          <acceleration>-1.23169 -1.78291 -2.77435 -0.100188 0.951708 1.42715</acceleration>
          <wrench>-0.020637 -0.029873 -0.046484 0 -0 0</wrench>
        </link>
        <link name='miro_head::head'>
          <pose>-0.008754 0.074785 0.007423 2.4e-05 0.472574 1.56963</pose>
          <velocity>-0.013126 0.000549 -0.000314 0.001906 0.040315 -0.025771</velocity>
          <acceleration>-4.83624 0.01417 -0.180031 0.942311 -1.39204 1.55569</acceleration>
          <wrench>-1.26612 0.00371 -0.047132 0 -0 0</wrench>
        </link>
        <link name='miro_neck::neck'>
          <pose>-0.008747 0.074078 0.00778 -1.8e-05 0.476519 1.56963</pose>
          <velocity>0.003435 -1.1e-05 -5.1e-05 -0.001459 -0.029026 0.031895</velocity>
          <acceleration>-4.39912 0.08877 -0.177832 2.66642 -0.260686 -1.90556</acceleration>
          <wrench>-0.331685 0.006693 -0.013408 0 -0 0</wrench>
        </link>
        <link name='miro_tail::tail'>
          <pose>-0.008743 0.120055 6.6e-05 -6.8e-05 -0.106239 1.56998</pose>
          <velocity>0.002271 -2.7e-05 -0.00026 -0.002136 -0.058803 0.002938</velocity>
          <acceleration>-3.4754 0.058816 0.074372 1.15738 0.400949 -1.97237</acceleration>
          <wrench>-0.196531 0.003326 0.004206 0 -0 0</wrench>
        </link>
        <link name='miro_tail::tail_gmbl'>
          <pose>-0.008693 0.120055 6.6e-05 -3.1e-05 -0.106238 1.56963</pose>
          <velocity>0.002292 -2.5e-05 -0.000257 -0.002129 -0.059042 0.00294</velocity>
          <acceleration>-3.46793 0.062154 0.072862 1.18456 0.856537 -1.9768</acceleration>
          <wrench>-0.196108 0.003515 0.00412 0 -0 0</wrench>
        </link>
      </model>
      <model name='miro02'>
        <pose>0.046152 -3.36063 0.000363 -3.4e-05 -0.108203 1.56235</pose>
        <scale>1 1 1</scale>
        <link name='miro_body::body'>
          <pose>0.046152 -3.36063 0.000363 -3.4e-05 -0.108203 1.56235</pose>
          <velocity>0.002336 -7.5e-05 -0.000466 -0.004753 -0.060917 0.005492</velocity>
          <acceleration>-0.70726 0.002437 -0.110124 2.8787 0.11432 -2.55278</acceleration>
          <wrench>-1.11096 0.003828 -0.172982 0 -0 0</wrench>
        </link>
        <link name='miro_body::wheel_lh'>
          <pose>0.046151 -3.36197 0.00027 -0.000237 -0.076988 1.56318</pose>
          <velocity>0.000169 -3e-06 -0.003121 -0.00454 -0.029032 0.005545</velocity>
          <acceleration>-2.30291 -0.188661 -9.39547 0.823875 0.032057 1.48996</acceleration>
          <wrench>-0.308684 -0.025288 -1.25938 0 -0 0</wrench>
        </link>
        <link name='miro_body::wheel_rh'>
          <pose>0.046128 -3.36205 0.000268 0.000207 -0.075082 1.56147</pose>
          <velocity>3.5e-05 -0.000399 0.002406 -0.009867 -0.026449 0.005214</velocity>
          <acceleration>-2.45461 -0.032434 8.99763 1.80506 -0.2713 -2.11947</acceleration>
          <wrench>-0.329018 -0.004347 1.20605 0 -0 0</wrench>
        </link>
        <link name='miro_gmbl::gmbl'>
          <pose>0.045761 -3.40675 0.007779 -6e-06 0.476505 1.56236</pose>
          <velocity>-0.000417 0.000282 -0.00041 7.3e-05 -0.018475 0.01971</velocity>
          <acceleration>-8.42915 0.052679 -0.220467 -1.70715 1.4786 -0.722543</acceleration>
          <wrench>-0.331013 0.002069 -0.008658 0 -0 0</wrench>
        </link>
        <link name='miro_head::ear_lh'>
          <pose>0.02399 -3.39063 -6e-06 0.043867 0.398034 1.42398</pose>
          <velocity>-0.012469 0.001269 0.000232 0.004007 0.040113 -0.013584</velocity>
          <acceleration>-0.023887 2.37132 3.31737 -0.77913 0.041764 0.339274</acceleration>
          <wrench>-0.001351 0.134096 0.187594 0 -0 0</wrench>
        </link>
        <link name='miro_head::ear_rh'>
          <pose>0.0669 -3.39172 0.000267 -0.041751 0.401066 1.69491</pose>
          <velocity>-0.012377 0.000686 -0.001482 0.003986 0.03961 -0.01352</velocity>
          <acceleration>-0.154658 -2.3726 -3.79749 -0.680943 -0.803076 0.27108</acceleration>
          <wrench>-0.008746 -0.134168 -0.214744 0 -0 0</wrench>
        </link>
        <link name='miro_head::eyelid_lh'>
          <pose>-0.020352 -3.34613 -0.021364 0.288477 0.199688 1.64253</pose>
          <velocity>-0.012078 0.001363 0.002298 0.001494 0.037525 -0.013587</velocity>
          <acceleration>-1.52333 1.55442 2.07671 0.526067 1.12335 0.087733</acceleration>
          <wrench>-0.025523 0.026044 0.034795 0 -0 0</wrench>
        </link>
        <link name='miro_head::eyelid_rh'>
          <pose>0.144313 -3.31901 -0.022788 -0.406409 0.072562 1.47342</pose>
          <velocity>-0.011714 0.000338 -0.004259 0.006487 0.037303 -0.013441</velocity>
          <acceleration>-1.5738 -1.6673 -2.75376 -1.70678 0.466239 0.381152</acceleration>
          <wrench>-0.026369 -0.027936 -0.046139 0 -0 0</wrench>
        </link>
        <link name='miro_head::head'>
          <pose>0.045759 -3.40609 0.007446 3.5e-05 0.472825 1.56235</pose>
          <velocity>-0.012262 0.000949 -0.000704 0.003996 0.039219 -0.013366</velocity>
          <acceleration>-4.85079 -0.045103 -0.272576 -0.637335 -1.43632 0.395909</acceleration>
          <wrench>-1.26993 -0.011808 -0.07136 0 -0 0</wrench>
        </link>
        <link name='miro_neck::neck'>
          <pose>0.045763 -3.40674 0.00778 -1.7e-05 0.476502 1.56236</pose>
          <velocity>0.003599 0.000164 -0.000372 -0.000812 -0.031845 0.032902</velocity>
          <acceleration>-4.41955 0.154698 -0.257474 2.89041 0.011149 2.36394</acceleration>
          <wrench>-0.333226 0.011664 -0.019413 0 -0 0</wrench>
        </link>
        <link name='miro_tail::tail'>
          <pose>0.046154 -3.36076 8.8e-05 -3.2e-05 -0.106384 1.56233</pose>
          <velocity>0.002407 -0.000128 -0.000568 -0.00546 -0.060453 0.005044</velocity>
          <acceleration>-3.48227 0.097709 0.100413 2.84488 0.514122 0.556475</acceleration>
          <wrench>-0.196919 0.005525 0.005678 0 -0 0</wrench>
        </link>
        <link name='miro_tail::tail_gmbl'>
          <pose>0.046151 -3.36076 8.8e-05 -3.4e-05 -0.106383 1.56235</pose>
          <velocity>0.002429 -0.000131 -0.000575 -0.00551 -0.060691 0.005043</velocity>
          <acceleration>-3.47675 0.100505 0.097932 2.8622 0.055979 0.535561</acceleration>
          <wrench>-0.196606 0.005683 0.005538 0 -0 0</wrench>
        </link>
      </model>
      <light name='sun'>
        <pose>0 0 10 0 -0 0</pose>
      </light>
    </state>
    <gui fullscreen='0'>
      <camera name='user_camera'>
        <pose>-0.126687 -0.420926 6.80976 3.14159 1.57079 3.14159</pose>
        <view_controller>orbit</view_controller>
        <projection_type>perspective</projection_type>
      </camera>
    </gui>
    <model name='miro01'>
      <frame name='miro_body::__model__' attached_to='miro_body::body'>
        <pose relative_to='__model__'>0 0 0 0 -0 0</pose>
      </frame>
      <link name='miro_body::body'>
        <inertial>
          <pose>-0.06 0 0.05 0 -0 0</pose>
          <mass>1.5708</mass>
          <inertia>
            <ixx>0.00523599</ixx>
            <ixy>0</ixy>
            <ixz>0</ixz>
            <iyy>0.00523599</iyy>
            <iyz>0</iyz>
            <izz>0.00785398</izz>
          </inertia>
        </inertial>
        <visual name='visual_valance'>
          <pose>0 0 0 0 -0 0</pose>
          <geometry>
            <mesh>
              <uri>model://miro_model/meshes/valance.dae</uri>
            </mesh>
          </geometry>
          <material>
            <script>
              <uri>file://media/materials/scripts/gazebo.material</uri>
              <name>Gazebo/Grey</name>
            </script>
          </material>
        </visual>
        <collision name='collision_valance'>
          <pose>0 0 0 0 -0 0</pose>
          <geometry>
            <mesh>
              <uri>model://miro_model/meshes/valance_collision.dae</uri>
            </mesh>
          </geometry>
          <surface>
            <friction>
              <ode>
                <mu>0.1</mu>
                <mu2>0.1</mu2>
              </ode>
              <torsional>
                <ode/>
              </torsional>
            </friction>
            <contact>
              <ode/>
            </contact>
            <bounce/>
          </surface>
          <max_contacts>10</max_contacts>
        </collision>
        <visual name='visual_skirt_lh'>
          <pose>0 0 0 0 -0 0</pose>
          <geometry>
            <mesh>
              <uri>model://miro_model/meshes/skirt_lh.dae</uri>
            </mesh>
          </geometry>
          <material>
            <script>
              <uri>file://media/materials/scripts/gazebo.material</uri>
              <name>Gazebo/Grey</name>
            </script>
          </material>
        </visual>
        <visual name='visual_skirt_rh'>
          <pose>0 0 0 0 -0 0</pose>
          <geometry>
            <mesh>
              <uri>model://miro_model/meshes/skirt_rh.dae</uri>
            </mesh>
          </geometry>
          <material>
            <script>
              <uri>file://media/materials/scripts/gazebo.material</uri>
              <name>Gazebo/Grey</name>
            </script>
          </material>
        </visual>
        <visual name='visual_cliff_sensor_L_asm'>
          <pose>0 0 0 0 -0 0</pose>
          <geometry>
            <mesh>
              <uri>model://miro_model/meshes/cliff_sensor_L_asm.dae</uri>
            </mesh>
          </geometry>
          <material>
            <script>
              <uri>file://media/materials/scripts/gazebo.material</uri>
              <name>Gazebo/DarkGrey</name>
            </script>
          </material>
        </visual>
        <visual name='visual_cliff_sensor_R_asm'>
          <pose>0 0 0 0 -0 0</pose>
          <geometry>
            <mesh>
              <uri>model://miro_model/meshes/cliff_sensor_R_asm.dae</uri>
            </mesh>
          </geometry>
          <material>
            <script>
              <uri>file://media/materials/scripts/gazebo.material</uri>
              <name>Gazebo/DarkGrey</name>
            </script>
          </material>
        </visual>
        <visual name='visual_light_sensor_holder_asm_L'>
          <pose>0 0 0 0 -0 0</pose>
          <geometry>
            <mesh>
              <uri>model://miro_model/meshes/light_sensor_holder_asm_L.dae</uri>
            </mesh>
          </geometry>
          <material>
            <script>
              <uri>file://media/materials/scripts/gazebo.material</uri>
              <name>Gazebo/DarkGrey</name>
            </script>
          </material>
        </visual>
        <visual name='visual_light_sensor_holder_asm_R'>
          <pose>0 0 0 0 -0 0</pose>
          <geometry>
            <mesh>
              <uri>model://miro_model/meshes/light_sensor_holder_asm_R.dae</uri>
            </mesh>
          </geometry>
          <material>
            <script>
              <uri>file://media/materials/scripts/gazebo.material</uri>
              <name>Gazebo/DarkGrey</name>
            </script>
          </material>
        </visual>
        <visual name='visual_body_shell'>
          <pose>0 0 0 0 -0 0</pose>
          <geometry>
            <mesh>
              <uri>model://miro_model/meshes/body_shell.dae</uri>
            </mesh>
          </geometry>
          <material>
            <script>
              <uri>file://media/materials/scripts/gazebo.material</uri>
              <name>Gazebo/White</name>
            </script>
          </material>
        </visual>
        <collision name='collision_body_shell'>
          <pose>0 0 0 0 -0 0</pose>
          <geometry>
            <mesh>
              <uri>model://miro_model/meshes/body_shell_collision.dae</uri>
            </mesh>
          </geometry>
          <surface>
            <friction>
              <ode>
                <mu>0.1</mu>
                <mu2>0.1</mu2>
              </ode>
              <torsional>
                <ode/>
              </torsional>
            </friction>
            <contact>
              <ode/>
            </contact>
            <bounce/>
          </surface>
          <max_contacts>10</max_contacts>
        </collision>
        <visual name='visual_slider'>
          <pose>0 0 0 0 -0 0</pose>
          <geometry>
            <mesh>
              <uri>model://miro_model/meshes/slider.dae</uri>
            </mesh>
          </geometry>
          <material>
            <script>
              <uri>file://media/materials/scripts/gazebo.material</uri>
              <name>Gazebo/DarkGrey</name>
            </script>
          </material>
        </visual>
        <collision name='collision_slider'>
          <pose>-0.1075 0 0.0264 0 -0 0</pose>
          <geometry>
            <sphere>
              <radius>0.015</radius>
            </sphere>
          </geometry>
          <surface>
            <friction>
              <ode>
                <mu>0.01</mu>
                <mu2>0.01</mu2>
              </ode>
              <torsional>
                <ode/>
              </torsional>
            </friction>
            <contact>
              <ode/>
            </contact>
            <bounce/>
          </surface>
          <max_contacts>10</max_contacts>
        </collision>
        <sensor name='acc_body' type='imu'>
          <pose>0 0 0 0 -0 0</pose>
          <always_on>1</always_on>
          <update_rate>50</update_rate>
          <visualize>0</visualize>
          <imu/>
        </sensor>
        <sensor name='cliff_l' type='sonar'>
          <pose>0.062 0.055 0.085 0 -0.52 0</pose>
          <always_on>1</always_on>
          <update_rate>50</update_rate>
          <visualize>0</visualize>
          <sonar>
            <min>0</min>
            <max>0.5</max>
            <radius>0.025</radius>
          </sonar>
        </sensor>
        <sensor name='cliff_r' type='sonar'>
          <pose>0.062 -0.055 0.085 0 -0.52 0</pose>
          <always_on>1</always_on>
          <update_rate>50</update_rate>
          <visualize>0</visualize>
          <sonar>
            <min>0</min>
            <max>0.5</max>
            <radius>0.025</radius>
          </sonar>
        </sensor>
        <sensor name='lightfl' type='camera'>
          <pose>0.055 0.065 0.08 -0 -0.06 0.52</pose>
          <camera>
            <horizontal_fov>1.57</horizontal_fov>
            <image>
              <width>16</width>
              <height>12</height>
            </image>
            <clip>
              <near>0.01</near>
              <far>10</far>
            </clip>
          </camera>
          <always_on>1</always_on>
          <update_rate>5</update_rate>
          <visualize>0</visualize>
        </sensor>
        <sensor name='lightfr' type='camera'>
          <pose>0.055 -0.065 0.08 0 -0.06 -0.52</pose>
          <camera>
            <horizontal_fov>1.57</horizontal_fov>
            <image>
              <width>16</width>
              <height>12</height>
            </image>
            <clip>
              <near>0.01</near>
              <far>10</far>
            </clip>
          </camera>
          <always_on>1</always_on>
          <update_rate>5</update_rate>
          <visualize>0</visualize>
        </sensor>
        <sensor name='lightrl' type='camera'>
          <pose>-0.125 0.072 0.06 0 -0.26 2.61</pose>
          <camera>
            <horizontal_fov>1.57</horizontal_fov>
            <image>
              <width>16</width>
              <height>12</height>
            </image>
            <clip>
              <near>0.01</near>
              <far>10</far>
            </clip>
          </camera>
          <always_on>1</always_on>
          <update_rate>5</update_rate>
          <visualize>0</visualize>
        </sensor>
        <sensor name='lightrr' type='camera'>
          <pose>-0.125 -0.072 0.06 0 -0.26 -2.61</pose>
          <camera>
            <horizontal_fov>1.57</horizontal_fov>
            <image>
              <width>16</width>
              <height>12</height>
            </image>
            <clip>
              <near>0.01</near>
              <far>10</far>
            </clip>
          </camera>
          <always_on>1</always_on>
          <update_rate>5</update_rate>
          <visualize>0</visualize>
        </sensor>
        <pose relative_to='miro_body::__model__'>0 0 0 0 -0 0</pose>
        <self_collide>0</self_collide>
        <enable_wind>0</enable_wind>
        <kinematic>0</kinematic>
      </link>
      <link name='miro_body::wheel_lh'>
        <inertial>
          <pose>0.00063 0.07779 0.044838 0 -0 0</pose>
          <mass>0.134041</mass>
          <inertia>
            <ixx>0.00014298</ixx>
            <ixy>0</ixy>
            <ixz>0</ixz>
            <iyy>0.00014298</iyy>
            <iyz>0</iyz>
            <izz>0.00014298</izz>
          </inertia>
        </inertial>
        <visual name='visual_wheel_tyre_lh'>
          <pose>0 0 0 0 -0 0</pose>
          <geometry>
            <mesh>
              <uri>model://miro_model/meshes/wheel_tyre_lh.dae</uri>
            </mesh>
          </geometry>
          <material>
            <script>
              <uri>file://media/materials/scripts/gazebo.material</uri>
              <name>Gazebo/DarkGrey</name>
            </script>
          </material>
        </visual>
        <collision name='collision_wheel_tyre_lh'>
          <pose>0.00063 0.07779 0.044838 -1.5446 0 0</pose>
          <geometry>
            <cylinder>
              <radius>0.045</radius>
              <length>0.002</length>
            </cylinder>
          </geometry>
          <surface>
            <friction>
              <ode>
                <mu>1</mu>
                <mu2>1</mu2>
              </ode>
              <torsional>
                <ode/>
              </torsional>
            </friction>
            <contact>
              <ode/>
            </contact>
            <bounce/>
          </surface>
          <max_contacts>10</max_contacts>
        </collision>
        <visual name='visual_wheel_rim_lh'>
          <pose>0 0 0 0 -0 0</pose>
          <geometry>
            <mesh>
              <uri>model://miro_model/meshes/wheel_rim_lh.dae</uri>
            </mesh>
          </geometry>
          <material>
            <script>
              <uri>file://media/materials/scripts/gazebo.material</uri>
              <name>Gazebo/Grey</name>
            </script>
          </material>
        </visual>
        <pose relative_to='miro_body::__model__'>0 0 0 0 -0 0</pose>
        <self_collide>0</self_collide>
        <enable_wind>0</enable_wind>
        <kinematic>0</kinematic>
      </link>
      <link name='miro_body::wheel_rh'>
        <inertial>
          <pose>0.00063 -0.07779 0.044838 0 -0 0</pose>
          <mass>0.134041</mass>
          <inertia>
            <ixx>0.00014298</ixx>
            <ixy>0</ixy>
            <ixz>0</ixz>
            <iyy>0.00014298</iyy>
            <iyz>0</iyz>
            <izz>0.00014298</izz>
          </inertia>
        </inertial>
        <visual name='visual_wheel_tyre_rh'>
          <pose>0 0 0 0 -0 0</pose>
          <geometry>
            <mesh>
              <uri>model://miro_model/meshes/wheel_tyre_rh.dae</uri>
            </mesh>
          </geometry>
          <material>
            <script>
              <uri>file://media/materials/scripts/gazebo.material</uri>
              <name>Gazebo/DarkGrey</name>
            </script>
          </material>
        </visual>
        <collision name='collision_wheel_tyre_rh'>
          <pose>0.00063 -0.07779 0.044838 1.5446 -0 0</pose>
          <geometry>
            <cylinder>
              <radius>0.045</radius>
              <length>0.002</length>
            </cylinder>
          </geometry>
          <surface>
            <friction>
              <ode>
                <mu>1</mu>
                <mu2>1</mu2>
              </ode>
              <torsional>
                <ode/>
              </torsional>
            </friction>
            <contact>
              <ode/>
            </contact>
            <bounce/>
          </surface>
          <max_contacts>10</max_contacts>
        </collision>
        <visual name='visual_wheel_rim_rh'>
          <pose>0 0 0 0 -0 0</pose>
          <geometry>
            <mesh>
              <uri>model://miro_model/meshes/wheel_rim_rh.dae</uri>
            </mesh>
          </geometry>
          <material>
            <script>
              <uri>file://media/materials/scripts/gazebo.material</uri>
              <name>Gazebo/Grey</name>
            </script>
          </material>
        </visual>
        <pose relative_to='miro_body::__model__'>0 0 0 0 -0 0</pose>
        <self_collide>0</self_collide>
        <enable_wind>0</enable_wind>
        <kinematic>0</kinematic>
      </link>
      <joint name='miro_body::body_wheel_lh' type='revolute'>
        <pose>0.00063 0.07779 0.044838 0 -0 0</pose>
        <parent>miro_body::body</parent>
        <child>miro_body::wheel_lh</child>
        <axis>
          <xyz>0 0.999657 0.026185</xyz>
          <dynamics>
            <friction>0.1</friction>
            <damping>0.1</damping>
            <spring_reference>0</spring_reference>
            <spring_stiffness>0</spring_stiffness>
          </dynamics>
          <limit>
            <lower>-1e+16</lower>
            <upper>1e+16</upper>
          </limit>
        </axis>
      </joint>
      <joint name='miro_body::body_wheel_rh' type='revolute'>
        <pose>0.00063 -0.07779 0.044838 0 -0 0</pose>
        <parent>miro_body::body</parent>
        <child>miro_body::wheel_rh</child>
        <axis>
          <xyz>0 0.999657 -0.026185</xyz>
          <dynamics>
            <friction>0.1</friction>
            <damping>0.1</damping>
            <spring_reference>0</spring_reference>
            <spring_stiffness>0</spring_stiffness>
          </dynamics>
          <limit>
            <lower>-1e+16</lower>
            <upper>1e+16</upper>
          </limit>
        </axis>
      </joint>
      <frame name='miro_tail::__model__' attached_to='miro_tail::tail_gmbl'>
        <pose relative_to='__model__'>0 0 0 0 -0 0</pose>
      </frame>
      <link name='miro_tail::tail_gmbl'>
        <inertial>
          <pose>-0.143 0 0.085 0 -0 0</pose>
          <mass>0.056549</mass>
          <inertia>
            <ixx>3.393e-05</ixx>
            <ixy>0</ixy>
            <ixz>0</ixz>
            <iyy>3.393e-05</iyy>
            <iyz>0</iyz>
            <izz>3.393e-05</izz>
          </inertia>
        </inertial>
        <pose relative_to='miro_tail::__model__'>0 0 0 0 -0 0</pose>
        <self_collide>0</self_collide>
        <enable_wind>0</enable_wind>
        <kinematic>0</kinematic>
      </link>
      <joint name='miro_tail::body_tail_gmbl' type='revolute'>
        <pose>-0.143 0 0.085 0 -0 0</pose>
        <parent>miro_body::body</parent>
        <child>miro_tail::tail_gmbl</child>
        <axis>
          <xyz>0 1 0</xyz>
          <limit>
            <lower>-1.57</lower>
            <upper>1.57</upper>
          </limit>
          <dynamics>
            <friction>0.01</friction>
            <damping>0.02</damping>
            <spring_reference>0</spring_reference>
            <spring_stiffness>0</spring_stiffness>
          </dynamics>
        </axis>
      </joint>
      <link name='miro_tail::tail'>
        <inertial>
          <pose>-0.143 0 0.085 0 -0 0</pose>
          <mass>0.056549</mass>
          <inertia>
            <ixx>3.393e-05</ixx>
            <ixy>0</ixy>
            <ixz>0</ixz>
            <iyy>3.393e-05</iyy>
            <iyz>0</iyz>
            <izz>3.393e-05</izz>
          </inertia>
        </inertial>
        <visual name='visual_tail'>
          <pose>0 0 0 0 -0 0</pose>
          <geometry>
            <mesh>
              <uri>model://miro_model/meshes/tail.dae</uri>
            </mesh>
          </geometry>
          <material>
            <script>
              <uri>file://media/materials/scripts/gazebo.material</uri>
              <name>Gazebo/Grey</name>
            </script>
          </material>
        </visual>
        <collision name='collision_tail'>
          <pose>0 0 0 0 -0 0</pose>
          <geometry>
            <mesh>
              <uri>model://miro_model/meshes/tail_collision.dae</uri>
            </mesh>
          </geometry>
          <surface>
            <friction>
              <ode>
                <mu>0.1</mu>
                <mu2>0.1</mu2>
              </ode>
              <torsional>
                <ode/>
              </torsional>
            </friction>
            <contact>
              <ode/>
            </contact>
            <bounce/>
          </surface>
          <max_contacts>10</max_contacts>
        </collision>
        <pose relative_to='miro_tail::__model__'>0 0 0 0 -0 0</pose>
        <self_collide>0</self_collide>
        <enable_wind>0</enable_wind>
        <kinematic>0</kinematic>
      </link>
      <joint name='miro_tail::tail_gmbl_tail' type='revolute'>
        <pose>-0.143 0 0.085 0 -0 0</pose>
        <parent>miro_tail::tail_gmbl</parent>
        <child>miro_tail::tail</child>
        <axis>
          <xyz>0 0 1</xyz>
          <limit>
            <lower>-1.57</lower>
            <upper>1.57</upper>
          </limit>
          <dynamics>
            <friction>0.01</friction>
            <damping>0.02</damping>
            <spring_reference>0</spring_reference>
            <spring_stiffness>0</spring_stiffness>
          </dynamics>
        </axis>
      </joint>
      <joint name='body_neck' type='revolute'>
        <pose>-0.002 0 0.081 0 -0 0</pose>
        <parent>miro_body::body</parent>
        <child>miro_neck::neck</child>
        <axis>
          <xyz>0 1 0</xyz>
          <limit>
            <lower>0</lower>
            <upper>1.57</upper>
          </limit>
          <dynamics>
            <spring_stiffness>0.4</spring_stiffness>
            <spring_reference>0</spring_reference>
            <friction>0.01</friction>
            <damping>0.1</damping>
          </dynamics>
        </axis>
      </joint>
      <frame name='miro_neck::__model__' attached_to='miro_neck::neck'>
        <pose relative_to='__model__'>0 0 0 0 -0 0</pose>
      </frame>
      <link name='miro_neck::neck'>
        <inertial>
          <pose>-0.002 0 0.141 0 -0 0</pose>
          <mass>0.075398</mass>
          <inertia>
            <ixx>9.802e-05</ixx>
            <ixy>0</ixy>
            <ixz>0</ixz>
            <iyy>9.802e-05</iyy>
            <iyz>0</iyz>
            <izz>1.508e-05</izz>
          </inertia>
        </inertial>
        <pose relative_to='miro_neck::__model__'>0 0 0 0 -0 0</pose>
        <self_collide>0</self_collide>
        <enable_wind>0</enable_wind>
        <kinematic>0</kinematic>
      </link>
      <joint name='neck_gmbl' type='revolute'>
        <pose>-0.002 0 0.201 0 -0 0</pose>
        <parent>miro_neck::neck</parent>
        <child>miro_gmbl::gmbl</child>
        <axis>
          <xyz>0 0 1</xyz>
          <limit>
            <lower>-1.57</lower>
            <upper>1.57</upper>
          </limit>
          <dynamics>
            <friction>0.01</friction>
            <damping>0.1</damping>
            <spring_reference>0</spring_reference>
            <spring_stiffness>0</spring_stiffness>
          </dynamics>
        </axis>
      </joint>
      <frame name='miro_gmbl::__model__' attached_to='miro_gmbl::gmbl'>
        <pose relative_to='__model__'>0 0 0 0 -0 0</pose>
      </frame>
      <link name='miro_gmbl::gmbl'>
        <inertial>
          <pose>-0.002 0 0.171 0 -0 0</pose>
          <mass>0.03927</mass>
          <inertia>
            <ixx>2.487e-05</ixx>
            <ixy>0</ixy>
            <ixz>0</ixz>
            <iyy>2.487e-05</iyy>
            <iyz>0</iyz>
            <izz>4.909e-05</izz>
          </inertia>
        </inertial>
        <visual name='visual_collar'>
          <pose>0 0 0 0 -0 0</pose>
          <geometry>
            <mesh>
              <uri>model://miro_model/meshes/collar.dae</uri>
            </mesh>
          </geometry>
          <material>
            <script>
              <uri>file://media/materials/scripts/gazebo.material</uri>
              <name>Gazebo/Red</name>
            </script>
          </material>
        </visual>
        <pose relative_to='miro_gmbl::__model__'>0 0 0 0 -0 0</pose>
        <self_collide>0</self_collide>
        <enable_wind>0</enable_wind>
        <kinematic>0</kinematic>
      </link>
      <joint name='gmbl_head' type='revolute'>
        <pose>-0.002 0 0.201 0 -0 0</pose>
        <parent>miro_gmbl::gmbl</parent>
        <child>miro_head::head</child>
        <axis>
          <xyz>0 1 0</xyz>
          <limit>
            <lower>-1.57</lower>
            <upper>1.57</upper>
          </limit>
          <dynamics>
            <spring_stiffness>0.1</spring_stiffness>
            <spring_reference>-0.5</spring_reference>
            <friction>0.01</friction>
            <damping>0.1</damping>
          </dynamics>
        </axis>
      </joint>
      <frame name='miro_head::__model__' attached_to='miro_head::head'>
        <pose relative_to='__model__'>0 0 0 0 -0 0</pose>
      </frame>
      <link name='miro_head::head'>
        <inertial>
          <pose>-0.002 0 0.221 0 -0 0</pose>
          <mass>0.261799</mass>
          <inertia>
            <ixx>0.00043633</ixx>
            <ixy>0</ixy>
            <ixz>0</ixz>
            <iyy>0.00043633</iyy>
            <iyz>0</iyz>
            <izz>0.00043633</izz>
          </inertia>
        </inertial>
        <visual name='visual_head_lower'>
          <pose>0 0 0 0 -0 0</pose>
          <geometry>
            <mesh>
              <uri>model://miro_model/meshes/head_lower.dae</uri>
            </mesh>
          </geometry>
          <material>
            <script>
              <uri>file://media/materials/scripts/gazebo.material</uri>
              <name>Gazebo/White</name>
            </script>
          </material>
        </visual>
        <collision name='collision_head_lower'>
          <pose>0 0 0 0 -0 0</pose>
          <geometry>
            <mesh>
              <uri>model://miro_model/meshes/head_lower_collision.dae</uri>
            </mesh>
          </geometry>
          <surface>
            <friction>
              <ode>
                <mu>0.1</mu>
                <mu2>0.1</mu2>
              </ode>
              <torsional>
                <ode/>
              </torsional>
            </friction>
            <contact>
              <ode/>
            </contact>
            <bounce/>
          </surface>
          <max_contacts>10</max_contacts>
        </collision>
        <visual name='visual_head_upper'>
          <pose>0 0 0 0 -0 0</pose>
          <geometry>
            <mesh>
              <uri>model://miro_model/meshes/head_upper.dae</uri>
            </mesh>
          </geometry>
          <material>
            <script>
              <uri>file://media/materials/scripts/gazebo.material</uri>
              <name>Gazebo/White</name>
            </script>
          </material>
        </visual>
        <collision name='collision_head_upper'>
          <pose>0 0 0 0 -0 0</pose>
          <geometry>
            <mesh>
              <uri>model://miro_model/meshes/head_upper_collision.dae</uri>
            </mesh>
          </geometry>
          <surface>
            <friction>
              <ode>
                <mu>0.1</mu>
                <mu2>0.1</mu2>
              </ode>
              <torsional>
                <ode/>
              </torsional>
            </friction>
            <contact>
              <ode/>
            </contact>
            <bounce/>
          </surface>
          <max_contacts>10</max_contacts>
        </collision>
        <visual name='visual_eyelid_lower_lh'>
          <pose>0 0 0 0 -0 0</pose>
          <geometry>
            <mesh>
              <uri>model://miro_model/meshes/eyelid_lower_lh.dae</uri>
            </mesh>
          </geometry>
          <material>
            <script>
              <uri>file://media/materials/scripts/gazebo.material</uri>
              <name>Gazebo/White</name>
            </script>
          </material>
        </visual>
        <visual name='visual_eyelid_lower_rh'>
          <pose>0 0 0 0 -0 0</pose>
          <geometry>
            <mesh>
              <uri>model://miro_model/meshes/eyelid_lower_rh.dae</uri>
            </mesh>
          </geometry>
          <material>
            <script>
              <uri>file://media/materials/scripts/gazebo.material</uri>
              <name>Gazebo/White</name>
            </script>
          </material>
        </visual>
        <visual name='visual_nose'>
          <pose>0 0 0 0 -0 0</pose>
          <geometry>
            <mesh>
              <uri>model://miro_model/meshes/nose.dae</uri>
            </mesh>
          </geometry>
          <material>
            <script>
              <uri>file://media/materials/scripts/gazebo.material</uri>
              <name>Gazebo/Grey</name>
            </script>
          </material>
        </visual>
        <collision name='collision_nose'>
          <pose>0 0 0 0 -0 0</pose>
          <geometry>
            <mesh>
              <uri>model://miro_model/meshes/nose_collision.dae</uri>
            </mesh>
          </geometry>
          <surface>
            <friction>
              <ode>
                <mu>0.3</mu>
                <mu2>0.3</mu2>
              </ode>
              <torsional>
                <ode/>
              </torsional>
            </friction>
            <contact>
              <ode/>
            </contact>
            <bounce/>
          </surface>
          <max_contacts>10</max_contacts>
        </collision>
        <visual name='visual_1'>
          <pose>0.029 0.033 0.252 0 -0 0</pose>
          <geometry>
            <sphere>
              <radius>0.018</radius>
            </sphere>
          </geometry>
          <material>
            <script>
              <uri>file://media/materials/scripts/gazebo.material</uri>
              <name>Gazebo/White</name>
            </script>
          </material>
        </visual>
        <visual name='visual_2'>
          <pose>0.0315 0.036 0.254 0 -0 0</pose>
          <geometry>
            <sphere>
              <radius>0.015</radius>
            </sphere>
          </geometry>
          <material>
            <script>
              <uri>file://media/materials/scripts/gazebo.material</uri>
              <name>Gazebo/DarkGrey</name>
            </script>
          </material>
        </visual>
        <visual name='visual_3'>
          <pose>0.029 -0.033 0.252 0 -0 0</pose>
          <geometry>
            <sphere>
              <radius>0.018</radius>
            </sphere>
          </geometry>
          <material>
            <script>
              <uri>file://media/materials/scripts/gazebo.material</uri>
              <name>Gazebo/White</name>
            </script>
          </material>
        </visual>
        <visual name='visual_4'>
          <pose>0.0315 -0.036 0.254 0 -0 0</pose>
          <geometry>
            <sphere>
              <radius>0.015</radius>
            </sphere>
          </geometry>
          <material>
            <script>
              <uri>file://media/materials/scripts/gazebo.material</uri>
              <name>Gazebo/DarkGrey</name>
            </script>
          </material>
        </visual>
        <sensor name='eye_l' type='wideanglecamera'>
          <pose>0.0377 0.0431 0.2595 -0.4262 -0.6816 0.6244</pose>
          <camera>
            <horizontal_fov>2.0944</horizontal_fov>
            <image>
              <width>1280</width>
              <height>720</height>
            </image>
            <clip>
              <near>0.006</near>
              <far>100</far>
            </clip>
            <lens>
              <type>custom</type>
              <scale_to_hfov>1</scale_to_hfov>
              <custom_function>
                <c1>2</c1>
                <c2>1.25</c2>
                <c3>0</c3>
                <f>1</f>
                <fun>sin</fun>
              </custom_function>
            </lens>
          </camera>
          <always_on>1</always_on>
          <update_rate>10</update_rate>
          <visualize>0</visualize>
        </sensor>
        <sensor name='eye_r' type='wideanglecamera'>
          <pose>0.0377 -0.0431 0.2595 0.4261 -0.6816 -0.6244</pose>
          <camera>
            <horizontal_fov>2.0944</horizontal_fov>
            <image>
              <width>1280</width>
              <height>720</height>
            </image>
            <clip>
              <near>0.006</near>
              <far>100</far>
            </clip>
            <lens>
              <type>custom</type>
              <scale_to_hfov>1</scale_to_hfov>
              <custom_function>
                <c1>2</c1>
                <c2>1.25</c2>
                <c3>0</c3>
                <f>1</f>
                <fun>sin</fun>
              </custom_function>
            </lens>
          </camera>
          <always_on>1</always_on>
          <update_rate>10</update_rate>
          <visualize>0</visualize>
        </sensor>
        <sensor name='eye_l_narrow' type='camera'>
          <pose>0.0377 0.0431 0.2595 -0.4262 -0.6816 0.6244</pose>
          <camera>
            <horizontal_fov>2.0944</horizontal_fov>
            <image>
              <width>1280</width>
              <height>720</height>
            </image>
            <clip>
              <near>0.006</near>
              <far>100</far>
            </clip>
          </camera>
          <always_on>1</always_on>
          <update_rate>10</update_rate>
          <visualize>0</visualize>
        </sensor>
        <sensor name='eye_r_narrow' type='camera'>
          <pose>0.0377 -0.0431 0.2595 0.4261 -0.6816 -0.6244</pose>
          <camera>
            <horizontal_fov>2.0944</horizontal_fov>
            <image>
              <width>1280</width>
              <height>720</height>
            </image>
            <clip>
              <near>0.006</near>
              <far>100</far>
            </clip>
          </camera>
          <always_on>1</always_on>
          <update_rate>10</update_rate>
          <visualize>0</visualize>
        </sensor>
        <sensor name='gaze' type='camera'>
          <pose>0.0577 0 0.2795 0 -0.785398 0</pose>
          <camera>
            <horizontal_fov>1</horizontal_fov>
            <image>
              <width>1280</width>
              <height>720</height>
            </image>
            <clip>
              <near>0.001</near>
              <far>100</far>
            </clip>
          </camera>
          <always_on>1</always_on>
          <update_rate>10</update_rate>
          <visualize>0</visualize>
        </sensor>
        <sensor name='overhead' type='camera'>
          <pose>0 0 1 0 1.22 0</pose>
          <camera>
            <horizontal_fov>1.0472</horizontal_fov>
            <image>
              <width>1280</width>
              <height>720</height>
            </image>
            <clip>
              <near>0.01</near>
              <far>2</far>
            </clip>
          </camera>
          <always_on>1</always_on>
          <update_rate>10</update_rate>
          <visualize>0</visualize>
        </sensor>
        <sensor name='acc_head' type='imu'>
          <pose>0 0 0 0 -0 0</pose>
          <always_on>1</always_on>
          <update_rate>50</update_rate>
          <visualize>0</visualize>
          <imu/>
        </sensor>
        <sensor name='sonar' type='sonar'>
          <pose>0.1 0 0.235 3.14159 -1.57079 3.14159</pose>
          <always_on>1</always_on>
          <update_rate>50</update_rate>
          <visualize>0</visualize>
          <sonar>
            <min>0</min>
            <max>1</max>
            <radius>0.309</radius>
          </sonar>
        </sensor>
        <pose relative_to='miro_head::__model__'>0 0 0 0 -0 0</pose>
        <self_collide>0</self_collide>
        <enable_wind>0</enable_wind>
        <kinematic>0</kinematic>
      </link>
      <link name='miro_head::eyelid_lh'>
        <inertial>
          <pose>0.029 0.032 0.252 0 -0 0</pose>
          <mass>0.016755</mass>
          <inertia>
            <ixx>4.47e-06</ixx>
            <ixy>0</ixy>
            <ixz>0</ixz>
            <iyy>4.47e-06</iyy>
            <iyz>0</iyz>
            <izz>4.47e-06</izz>
          </inertia>
        </inertial>
        <visual name='visual_eyelid_lh'>
          <pose>0 0 0 0 -0 0</pose>
          <geometry>
            <mesh>
              <uri>model://miro_model/meshes/eyelid_lh.dae</uri>
            </mesh>
          </geometry>
          <material>
            <script>
              <uri>file://media/materials/scripts/gazebo.material</uri>
              <name>Gazebo/White</name>
            </script>
          </material>
        </visual>
        <pose relative_to='miro_head::__model__'>0 0 0 0 -0 0</pose>
        <self_collide>0</self_collide>
        <enable_wind>0</enable_wind>
        <kinematic>0</kinematic>
      </link>
      <link name='miro_head::eyelid_rh'>
        <inertial>
          <pose>0.029 -0.032 0.252 0 -0 0</pose>
          <mass>0.016755</mass>
          <inertia>
            <ixx>4.47e-06</ixx>
            <ixy>0</ixy>
            <ixz>0</ixz>
            <iyy>4.47e-06</iyy>
            <iyz>0</iyz>
            <izz>4.47e-06</izz>
          </inertia>
        </inertial>
        <visual name='visual_eyelid_rh'>
          <pose>0 0 0 0 -0 0</pose>
          <geometry>
            <mesh>
              <uri>model://miro_model/meshes/eyelid_rh.dae</uri>
            </mesh>
          </geometry>
          <material>
            <script>
              <uri>file://media/materials/scripts/gazebo.material</uri>
              <name>Gazebo/White</name>
            </script>
          </material>
        </visual>
        <pose relative_to='miro_head::__model__'>0 0 0 0 -0 0</pose>
        <self_collide>0</self_collide>
        <enable_wind>0</enable_wind>
        <kinematic>0</kinematic>
      </link>
      <joint name='miro_head::head_eyelid_lh' type='revolute'>
        <pose>0.029 0.032 0.252 0 -0 0</pose>
        <parent>miro_head::head</parent>
        <child>miro_head::eyelid_lh</child>
        <axis>
          <xyz>-0.675 0.675 -0.2978</xyz>
          <limit>
            <lower>-1.57</lower>
            <upper>1.57</upper>
          </limit>
          <dynamics>
            <friction>0.1</friction>
            <damping>0.1</damping>
            <spring_reference>-0.5</spring_reference>
            <spring_stiffness>0.02</spring_stiffness>
          </dynamics>
        </axis>
        <physics>
          <ode>
            <cfm_damping>1</cfm_damping>
            <implicit_spring_damper>1</implicit_spring_damper>
            <limit>
              <cfm>0</cfm>
              <erp>0.2</erp>
            </limit>
          </ode>
        </physics>
      </joint>
      <joint name='miro_head::head_eyelid_rh' type='revolute'>
        <pose>0.029 -0.032 0.252 0 -0 0</pose>
        <parent>miro_head::head</parent>
        <child>miro_head::eyelid_rh</child>
        <axis>
          <xyz>0.675 0.675 0.2978</xyz>
          <limit>
            <lower>-1.57</lower>
            <upper>1.57</upper>
          </limit>
          <dynamics>
            <friction>0.1</friction>
            <damping>0.1</damping>
            <spring_reference>-0.5</spring_reference>
            <spring_stiffness>0.02</spring_stiffness>
          </dynamics>
        </axis>
        <physics>
          <ode>
            <cfm_damping>1</cfm_damping>
            <implicit_spring_damper>1</implicit_spring_damper>
            <limit>
              <cfm>0</cfm>
              <erp>0.2</erp>
            </limit>
          </ode>
        </physics>
      </joint>
      <link name='miro_head::ear_lh'>
        <inertial>
          <pose>-0.0437 0.0474 0.2773 0 -0 0</pose>
          <mass>0.056549</mass>
          <inertia>
            <ixx>3.393e-05</ixx>
            <ixy>0</ixy>
            <ixz>0</ixz>
            <iyy>3.393e-05</iyy>
            <iyz>0</iyz>
            <izz>3.393e-05</izz>
          </inertia>
        </inertial>
        <visual name='visual_ear_lh'>
          <pose>0 0 0 0 -0 0</pose>
          <geometry>
            <mesh>
              <uri>model://miro_model/meshes/ear_lh.dae</uri>
            </mesh>
          </geometry>
          <material>
            <script>
              <uri>file://media/materials/scripts/gazebo.material</uri>
              <name>Gazebo/Grey</name>
            </script>
          </material>
        </visual>
        <collision name='collision_ear_lh'>
          <pose>0 0 0 0 -0 0</pose>
          <geometry>
            <mesh>
              <uri>model://miro_model/meshes/ear_lh_collision.dae</uri>
            </mesh>
          </geometry>
          <surface>
            <friction>
              <ode>
                <mu>0.3</mu>
                <mu2>0.3</mu2>
              </ode>
              <torsional>
                <ode/>
              </torsional>
            </friction>
            <contact>
              <ode/>
            </contact>
            <bounce/>
          </surface>
          <max_contacts>10</max_contacts>
        </collision>
        <pose relative_to='miro_head::__model__'>0 0 0 0 -0 0</pose>
        <self_collide>0</self_collide>
        <enable_wind>0</enable_wind>
        <kinematic>0</kinematic>
      </link>
      <link name='miro_head::ear_rh'>
        <inertial>
          <pose>-0.0437 -0.0474 0.2773 0 -0 0</pose>
          <mass>0.056549</mass>
          <inertia>
            <ixx>3.393e-05</ixx>
            <ixy>0</ixy>
            <ixz>0</ixz>
            <iyy>3.393e-05</iyy>
            <iyz>0</iyz>
            <izz>3.393e-05</izz>
          </inertia>
        </inertial>
        <visual name='visual_ear_rh'>
          <pose>0 0 0 0 -0 0</pose>
          <geometry>
            <mesh>
              <uri>model://miro_model/meshes/ear_rh.dae</uri>
            </mesh>
          </geometry>
          <material>
            <script>
              <uri>file://media/materials/scripts/gazebo.material</uri>
              <name>Gazebo/Grey</name>
            </script>
          </material>
        </visual>
        <collision name='collision_ear_rh'>
          <pose>0 0 0 0 -0 0</pose>
          <geometry>
            <mesh>
              <uri>model://miro_model/meshes/ear_rh_collision.dae</uri>
            </mesh>
          </geometry>
          <surface>
            <friction>
              <ode>
                <mu>0.3</mu>
                <mu2>0.3</mu2>
              </ode>
              <torsional>
                <ode/>
              </torsional>
            </friction>
            <contact>
              <ode/>
            </contact>
            <bounce/>
          </surface>
          <max_contacts>10</max_contacts>
        </collision>
        <pose relative_to='miro_head::__model__'>0 0 0 0 -0 0</pose>
        <self_collide>0</self_collide>
        <enable_wind>0</enable_wind>
        <kinematic>0</kinematic>
      </link>
      <joint name='miro_head::head_ear_lh' type='revolute'>
        <pose>-0.0437 0.0474 0.2773 0 -0 0</pose>
        <parent>miro_head::head</parent>
        <child>miro_head::ear_lh</child>
        <axis>
          <xyz>-0.573 0.4344 0.6949</xyz>
          <limit>
            <lower>-1.57</lower>
            <upper>1.57</upper>
          </limit>
          <dynamics>
            <friction>0.01</friction>
            <damping>0.001</damping>
            <spring_reference>0</spring_reference>
            <spring_stiffness>0</spring_stiffness>
          </dynamics>
        </axis>
      </joint>
      <joint name='miro_head::head_ear_rh' type='revolute'>
        <pose>-0.0437 -0.0474 0.2773 0 -0 0</pose>
        <parent>miro_head::head</parent>
        <child>miro_head::ear_rh</child>
        <axis>
          <xyz>-0.573 -0.4344 0.6949</xyz>
          <limit>
            <lower>-1.57</lower>
            <upper>1.57</upper>
          </limit>
          <dynamics>
            <friction>0.01</friction>
            <damping>0.001</damping>
            <spring_reference>0</spring_reference>
            <spring_stiffness>0</spring_stiffness>
          </dynamics>
        </axis>
      </joint>
      <plugin name='miro_model' filename='libmiro_gazebo.so'/>
      <pose>0 0 0 0 -0 0</pose>
    </model>
    <model name='miro02'>
      <frame name='miro_body::__model__' attached_to='miro_body::body'>
        <pose relative_to='__model__'>0 0 0 0 -0 0</pose>
      </frame>
      <link name='miro_body::body'>
        <inertial>
          <pose>-0.06 0 0.05 0 -0 0</pose>
          <mass>1.5708</mass>
          <inertia>
            <ixx>0.00523599</ixx>
            <ixy>0</ixy>
            <ixz>0</ixz>
            <iyy>0.00523599</iyy>
            <iyz>0</iyz>
            <izz>0.00785398</izz>
          </inertia>
        </inertial>
        <visual name='visual_valance'>
          <pose>0 0 0 0 -0 0</pose>
          <geometry>
            <mesh>
              <uri>model://miro_model/meshes/valance.dae</uri>
            </mesh>
          </geometry>
          <material>
            <script>
              <uri>file://media/materials/scripts/gazebo.material</uri>
              <name>Gazebo/Grey</name>
            </script>
          </material>
        </visual>
        <collision name='collision_valance'>
          <pose>0 0 0 0 -0 0</pose>
          <geometry>
            <mesh>
              <uri>model://miro_model/meshes/valance_collision.dae</uri>
            </mesh>
          </geometry>
          <surface>
            <friction>
              <ode>
                <mu>0.1</mu>
                <mu2>0.1</mu2>
              </ode>
              <torsional>
                <ode/>
              </torsional>
            </friction>
            <contact>
              <ode/>
            </contact>
            <bounce/>
          </surface>
          <max_contacts>10</max_contacts>
        </collision>
        <visual name='visual_skirt_lh'>
          <pose>0 0 0 0 -0 0</pose>
          <geometry>
            <mesh>
              <uri>model://miro_model/meshes/skirt_lh.dae</uri>
            </mesh>
          </geometry>
          <material>
            <script>
              <uri>file://media/materials/scripts/gazebo.material</uri>
              <name>Gazebo/Grey</name>
            </script>
          </material>
        </visual>
        <visual name='visual_skirt_rh'>
          <pose>0 0 0 0 -0 0</pose>
          <geometry>
            <mesh>
              <uri>model://miro_model/meshes/skirt_rh.dae</uri>
            </mesh>
          </geometry>
          <material>
            <script>
              <uri>file://media/materials/scripts/gazebo.material</uri>
              <name>Gazebo/Grey</name>
            </script>
          </material>
        </visual>
        <visual name='visual_cliff_sensor_L_asm'>
          <pose>0 0 0 0 -0 0</pose>
          <geometry>
            <mesh>
              <uri>model://miro_model/meshes/cliff_sensor_L_asm.dae</uri>
            </mesh>
          </geometry>
          <material>
            <script>
              <uri>file://media/materials/scripts/gazebo.material</uri>
              <name>Gazebo/DarkGrey</name>
            </script>
          </material>
        </visual>
        <visual name='visual_cliff_sensor_R_asm'>
          <pose>0 0 0 0 -0 0</pose>
          <geometry>
            <mesh>
              <uri>model://miro_model/meshes/cliff_sensor_R_asm.dae</uri>
            </mesh>
          </geometry>
          <material>
            <script>
              <uri>file://media/materials/scripts/gazebo.material</uri>
              <name>Gazebo/DarkGrey</name>
            </script>
          </material>
        </visual>
        <visual name='visual_light_sensor_holder_asm_L'>
          <pose>0 0 0 0 -0 0</pose>
          <geometry>
            <mesh>
              <uri>model://miro_model/meshes/light_sensor_holder_asm_L.dae</uri>
            </mesh>
          </geometry>
          <material>
            <script>
              <uri>file://media/materials/scripts/gazebo.material</uri>
              <name>Gazebo/DarkGrey</name>
            </script>
          </material>
        </visual>
        <visual name='visual_light_sensor_holder_asm_R'>
          <pose>0 0 0 0 -0 0</pose>
          <geometry>
            <mesh>
              <uri>model://miro_model/meshes/light_sensor_holder_asm_R.dae</uri>
            </mesh>
          </geometry>
          <material>
            <script>
              <uri>file://media/materials/scripts/gazebo.material</uri>
              <name>Gazebo/DarkGrey</name>
            </script>
          </material>
        </visual>
        <visual name='visual_body_shell'>
          <pose>0 0 0 0 -0 0</pose>
          <geometry>
            <mesh>
              <uri>model://miro_model/meshes/body_shell.dae</uri>
            </mesh>
          </geometry>
          <material>
            <script>
              <uri>file://media/materials/scripts/gazebo.material</uri>
              <name>Gazebo/White</name>
            </script>
          </material>
        </visual>
        <collision name='collision_body_shell'>
          <pose>0 0 0 0 -0 0</pose>
          <geometry>
            <mesh>
              <uri>model://miro_model/meshes/body_shell_collision.dae</uri>
            </mesh>
          </geometry>
          <surface>
            <friction>
              <ode>
                <mu>0.1</mu>
                <mu2>0.1</mu2>
              </ode>
              <torsional>
                <ode/>
              </torsional>
            </friction>
            <contact>
              <ode/>
            </contact>
            <bounce/>
          </surface>
          <max_contacts>10</max_contacts>
        </collision>
        <visual name='visual_slider'>
          <pose>0 0 0 0 -0 0</pose>
          <geometry>
            <mesh>
              <uri>model://miro_model/meshes/slider.dae</uri>
            </mesh>
          </geometry>
          <material>
            <script>
              <uri>file://media/materials/scripts/gazebo.material</uri>
              <name>Gazebo/DarkGrey</name>
            </script>
          </material>
        </visual>
        <collision name='collision_slider'>
          <pose>-0.1075 0 0.0264 0 -0 0</pose>
          <geometry>
            <sphere>
              <radius>0.015</radius>
            </sphere>
          </geometry>
          <surface>
            <friction>
              <ode>
                <mu>0.01</mu>
                <mu2>0.01</mu2>
              </ode>
              <torsional>
                <ode/>
              </torsional>
            </friction>
            <contact>
              <ode/>
            </contact>
            <bounce/>
          </surface>
          <max_contacts>10</max_contacts>
        </collision>
        <sensor name='acc_body' type='imu'>
          <pose>0 0 0 0 -0 0</pose>
          <always_on>1</always_on>
          <update_rate>50</update_rate>
          <visualize>0</visualize>
          <imu/>
        </sensor>
        <sensor name='cliff_l' type='sonar'>
          <pose>0.062 0.055 0.085 0 -0.52 0</pose>
          <always_on>1</always_on>
          <update_rate>50</update_rate>
          <visualize>0</visualize>
          <sonar>
            <min>0</min>
            <max>0.5</max>
            <radius>0.025</radius>
          </sonar>
        </sensor>
        <sensor name='cliff_r' type='sonar'>
          <pose>0.062 -0.055 0.085 0 -0.52 0</pose>
          <always_on>1</always_on>
          <update_rate>50</update_rate>
          <visualize>0</visualize>
          <sonar>
            <min>0</min>
            <max>0.5</max>
            <radius>0.025</radius>
          </sonar>
        </sensor>
        <sensor name='lightfl' type='camera'>
          <pose>0.055 0.065 0.08 -0 -0.06 0.52</pose>
          <camera>
            <horizontal_fov>1.57</horizontal_fov>
            <image>
              <width>16</width>
              <height>12</height>
            </image>
            <clip>
              <near>0.01</near>
              <far>10</far>
            </clip>
          </camera>
          <always_on>1</always_on>
          <update_rate>5</update_rate>
          <visualize>0</visualize>
        </sensor>
        <sensor name='lightfr' type='camera'>
          <pose>0.055 -0.065 0.08 0 -0.06 -0.52</pose>
          <camera>
            <horizontal_fov>1.57</horizontal_fov>
            <image>
              <width>16</width>
              <height>12</height>
            </image>
            <clip>
              <near>0.01</near>
              <far>10</far>
            </clip>
          </camera>
          <always_on>1</always_on>
          <update_rate>5</update_rate>
          <visualize>0</visualize>
        </sensor>
        <sensor name='lightrl' type='camera'>
          <pose>-0.125 0.072 0.06 0 -0.26 2.61</pose>
          <camera>
            <horizontal_fov>1.57</horizontal_fov>
            <image>
              <width>16</width>
              <height>12</height>
            </image>
            <clip>
              <near>0.01</near>
              <far>10</far>
            </clip>
          </camera>
          <always_on>1</always_on>
          <update_rate>5</update_rate>
          <visualize>0</visualize>
        </sensor>
        <sensor name='lightrr' type='camera'>
          <pose>-0.125 -0.072 0.06 0 -0.26 -2.61</pose>
          <camera>
            <horizontal_fov>1.57</horizontal_fov>
            <image>
              <width>16</width>
              <height>12</height>
            </image>
            <clip>
              <near>0.01</near>
              <far>10</far>
            </clip>
          </camera>
          <always_on>1</always_on>
          <update_rate>5</update_rate>
          <visualize>0</visualize>
        </sensor>
        <pose relative_to='miro_body::__model__'>0 0 0 0 -0 0</pose>
        <self_collide>0</self_collide>
        <enable_wind>0</enable_wind>
        <kinematic>0</kinematic>
      </link>
      <link name='miro_body::wheel_lh'>
        <inertial>
          <pose>0.00063 0.07779 0.044838 0 -0 0</pose>
          <mass>0.134041</mass>
          <inertia>
            <ixx>0.00014298</ixx>
            <ixy>0</ixy>
            <ixz>0</ixz>
            <iyy>0.00014298</iyy>
            <iyz>0</iyz>
            <izz>0.00014298</izz>
          </inertia>
        </inertial>
        <visual name='visual_wheel_tyre_lh'>
          <pose>0 0 0 0 -0 0</pose>
          <geometry>
            <mesh>
              <uri>model://miro_model/meshes/wheel_tyre_lh.dae</uri>
            </mesh>
          </geometry>
          <material>
            <script>
              <uri>file://media/materials/scripts/gazebo.material</uri>
              <name>Gazebo/DarkGrey</name>
            </script>
          </material>
        </visual>
        <collision name='collision_wheel_tyre_lh'>
          <pose>0.00063 0.07779 0.044838 -1.5446 0 0</pose>
          <geometry>
            <cylinder>
              <radius>0.045</radius>
              <length>0.002</length>
            </cylinder>
          </geometry>
          <surface>
            <friction>
              <ode>
                <mu>1</mu>
                <mu2>1</mu2>
              </ode>
              <torsional>
                <ode/>
              </torsional>
            </friction>
            <contact>
              <ode/>
            </contact>
            <bounce/>
          </surface>
          <max_contacts>10</max_contacts>
        </collision>
        <visual name='visual_wheel_rim_lh'>
          <pose>0 0 0 0 -0 0</pose>
          <geometry>
            <mesh>
              <uri>model://miro_model/meshes/wheel_rim_lh.dae</uri>
            </mesh>
          </geometry>
          <material>
            <script>
              <uri>file://media/materials/scripts/gazebo.material</uri>
              <name>Gazebo/Grey</name>
            </script>
          </material>
        </visual>
        <pose relative_to='miro_body::__model__'>0 0 0 0 -0 0</pose>
        <self_collide>0</self_collide>
        <enable_wind>0</enable_wind>
        <kinematic>0</kinematic>
      </link>
      <link name='miro_body::wheel_rh'>
        <inertial>
          <pose>0.00063 -0.07779 0.044838 0 -0 0</pose>
          <mass>0.134041</mass>
          <inertia>
            <ixx>0.00014298</ixx>
            <ixy>0</ixy>
            <ixz>0</ixz>
            <iyy>0.00014298</iyy>
            <iyz>0</iyz>
            <izz>0.00014298</izz>
          </inertia>
        </inertial>
        <visual name='visual_wheel_tyre_rh'>
          <pose>0 0 0 0 -0 0</pose>
          <geometry>
            <mesh>
              <uri>model://miro_model/meshes/wheel_tyre_rh.dae</uri>
            </mesh>
          </geometry>
          <material>
            <script>
              <uri>file://media/materials/scripts/gazebo.material</uri>
              <name>Gazebo/DarkGrey</name>
            </script>
          </material>
        </visual>
        <collision name='collision_wheel_tyre_rh'>
          <pose>0.00063 -0.07779 0.044838 1.5446 -0 0</pose>
          <geometry>
            <cylinder>
              <radius>0.045</radius>
              <length>0.002</length>
            </cylinder>
          </geometry>
          <surface>
            <friction>
              <ode>
                <mu>1</mu>
                <mu2>1</mu2>
              </ode>
              <torsional>
                <ode/>
              </torsional>
            </friction>
            <contact>
              <ode/>
            </contact>
            <bounce/>
          </surface>
          <max_contacts>10</max_contacts>
        </collision>
        <visual name='visual_wheel_rim_rh'>
          <pose>0 0 0 0 -0 0</pose>
          <geometry>
            <mesh>
              <uri>model://miro_model/meshes/wheel_rim_rh.dae</uri>
            </mesh>
          </geometry>
          <material>
            <script>
              <uri>file://media/materials/scripts/gazebo.material</uri>
              <name>Gazebo/Grey</name>
            </script>
          </material>
        </visual>
        <pose relative_to='miro_body::__model__'>0 0 0 0 -0 0</pose>
        <self_collide>0</self_collide>
        <enable_wind>0</enable_wind>
        <kinematic>0</kinematic>
      </link>
      <joint name='miro_body::body_wheel_lh' type='revolute'>
        <pose>0.00063 0.07779 0.044838 0 -0 0</pose>
        <parent>miro_body::body</parent>
        <child>miro_body::wheel_lh</child>
        <axis>
          <xyz>0 0.999657 0.026185</xyz>
          <dynamics>
            <friction>0.1</friction>
            <damping>0.1</damping>
            <spring_reference>0</spring_reference>
            <spring_stiffness>0</spring_stiffness>
          </dynamics>
          <limit>
            <lower>-1e+16</lower>
            <upper>1e+16</upper>
          </limit>
        </axis>
      </joint>
      <joint name='miro_body::body_wheel_rh' type='revolute'>
        <pose>0.00063 -0.07779 0.044838 0 -0 0</pose>
        <parent>miro_body::body</parent>
        <child>miro_body::wheel_rh</child>
        <axis>
          <xyz>0 0.999657 -0.026185</xyz>
          <dynamics>
            <friction>0.1</friction>
            <damping>0.1</damping>
            <spring_reference>0</spring_reference>
            <spring_stiffness>0</spring_stiffness>
          </dynamics>
          <limit>
            <lower>-1e+16</lower>
            <upper>1e+16</upper>
          </limit>
        </axis>
      </joint>
      <frame name='miro_tail::__model__' attached_to='miro_tail::tail_gmbl'>
        <pose relative_to='__model__'>0 0 0 0 -0 0</pose>
      </frame>
      <link name='miro_tail::tail_gmbl'>
        <inertial>
          <pose>-0.143 0 0.085 0 -0 0</pose>
          <mass>0.056549</mass>
          <inertia>
            <ixx>3.393e-05</ixx>
            <ixy>0</ixy>
            <ixz>0</ixz>
            <iyy>3.393e-05</iyy>
            <iyz>0</iyz>
            <izz>3.393e-05</izz>
          </inertia>
        </inertial>
        <pose relative_to='miro_tail::__model__'>0 0 0 0 -0 0</pose>
        <self_collide>0</self_collide>
        <enable_wind>0</enable_wind>
        <kinematic>0</kinematic>
      </link>
      <joint name='miro_tail::body_tail_gmbl' type='revolute'>
        <pose>-0.143 0 0.085 0 -0 0</pose>
        <parent>miro_body::body</parent>
        <child>miro_tail::tail_gmbl</child>
        <axis>
          <xyz>0 1 0</xyz>
          <limit>
            <lower>-1.57</lower>
            <upper>1.57</upper>
          </limit>
          <dynamics>
            <friction>0.01</friction>
            <damping>0.02</damping>
            <spring_reference>0</spring_reference>
            <spring_stiffness>0</spring_stiffness>
          </dynamics>
        </axis>
      </joint>
      <link name='miro_tail::tail'>
        <inertial>
          <pose>-0.143 0 0.085 0 -0 0</pose>
          <mass>0.056549</mass>
          <inertia>
            <ixx>3.393e-05</ixx>
            <ixy>0</ixy>
            <ixz>0</ixz>
            <iyy>3.393e-05</iyy>
            <iyz>0</iyz>
            <izz>3.393e-05</izz>
          </inertia>
        </inertial>
        <visual name='visual_tail'>
          <pose>0 0 0 0 -0 0</pose>
          <geometry>
            <mesh>
              <uri>model://miro_model/meshes/tail.dae</uri>
            </mesh>
          </geometry>
          <material>
            <script>
              <uri>file://media/materials/scripts/gazebo.material</uri>
              <name>Gazebo/Grey</name>
            </script>
          </material>
        </visual>
        <collision name='collision_tail'>
          <pose>0 0 0 0 -0 0</pose>
          <geometry>
            <mesh>
              <uri>model://miro_model/meshes/tail_collision.dae</uri>
            </mesh>
          </geometry>
          <surface>
            <friction>
              <ode>
                <mu>0.1</mu>
                <mu2>0.1</mu2>
              </ode>
              <torsional>
                <ode/>
              </torsional>
            </friction>
            <contact>
              <ode/>
            </contact>
            <bounce/>
          </surface>
          <max_contacts>10</max_contacts>
        </collision>
        <pose relative_to='miro_tail::__model__'>0 0 0 0 -0 0</pose>
        <self_collide>0</self_collide>
        <enable_wind>0</enable_wind>
        <kinematic>0</kinematic>
      </link>
      <joint name='miro_tail::tail_gmbl_tail' type='revolute'>
        <pose>-0.143 0 0.085 0 -0 0</pose>
        <parent>miro_tail::tail_gmbl</parent>
        <child>miro_tail::tail</child>
        <axis>
          <xyz>0 0 1</xyz>
          <limit>
            <lower>-1.57</lower>
            <upper>1.57</upper>
          </limit>
          <dynamics>
            <friction>0.01</friction>
            <damping>0.02</damping>
            <spring_reference>0</spring_reference>
            <spring_stiffness>0</spring_stiffness>
          </dynamics>
        </axis>
      </joint>
      <joint name='body_neck' type='revolute'>
        <pose>-0.002 0 0.081 0 -0 0</pose>
        <parent>miro_body::body</parent>
        <child>miro_neck::neck</child>
        <axis>
          <xyz>0 1 0</xyz>
          <limit>
            <lower>0</lower>
            <upper>1.57</upper>
          </limit>
          <dynamics>
            <spring_stiffness>0.4</spring_stiffness>
            <spring_reference>0</spring_reference>
            <friction>0.01</friction>
            <damping>0.1</damping>
          </dynamics>
        </axis>
      </joint>
      <frame name='miro_neck::__model__' attached_to='miro_neck::neck'>
        <pose relative_to='__model__'>0 0 0 0 -0 0</pose>
      </frame>
      <link name='miro_neck::neck'>
        <inertial>
          <pose>-0.002 0 0.141 0 -0 0</pose>
          <mass>0.075398</mass>
          <inertia>
            <ixx>9.802e-05</ixx>
            <ixy>0</ixy>
            <ixz>0</ixz>
            <iyy>9.802e-05</iyy>
            <iyz>0</iyz>
            <izz>1.508e-05</izz>
          </inertia>
        </inertial>
        <pose relative_to='miro_neck::__model__'>0 0 0 0 -0 0</pose>
        <self_collide>0</self_collide>
        <enable_wind>0</enable_wind>
        <kinematic>0</kinematic>
      </link>
      <joint name='neck_gmbl' type='revolute'>
        <pose>-0.002 0 0.201 0 -0 0</pose>
        <parent>miro_neck::neck</parent>
        <child>miro_gmbl::gmbl</child>
        <axis>
          <xyz>0 0 1</xyz>
          <limit>
            <lower>-1.57</lower>
            <upper>1.57</upper>
          </limit>
          <dynamics>
            <friction>0.01</friction>
            <damping>0.1</damping>
            <spring_reference>0</spring_reference>
            <spring_stiffness>0</spring_stiffness>
          </dynamics>
        </axis>
      </joint>
      <frame name='miro_gmbl::__model__' attached_to='miro_gmbl::gmbl'>
        <pose relative_to='__model__'>0 0 0 0 -0 0</pose>
      </frame>
      <link name='miro_gmbl::gmbl'>
        <inertial>
          <pose>-0.002 0 0.171 0 -0 0</pose>
          <mass>0.03927</mass>
          <inertia>
            <ixx>2.487e-05</ixx>
            <ixy>0</ixy>
            <ixz>0</ixz>
            <iyy>2.487e-05</iyy>
            <iyz>0</iyz>
            <izz>4.909e-05</izz>
          </inertia>
        </inertial>
        <visual name='visual_collar'>
          <pose>0 0 0 0 -0 0</pose>
          <geometry>
            <mesh>
              <uri>model://miro_model/meshes/collar.dae</uri>
            </mesh>
          </geometry>
          <material>
            <script>
              <uri>file://media/materials/scripts/gazebo.material</uri>
              <name>Gazebo/Red</name>
            </script>
          </material>
        </visual>
        <pose relative_to='miro_gmbl::__model__'>0 0 0 0 -0 0</pose>
        <self_collide>0</self_collide>
        <enable_wind>0</enable_wind>
        <kinematic>0</kinematic>
      </link>
      <joint name='gmbl_head' type='revolute'>
        <pose>-0.002 0 0.201 0 -0 0</pose>
        <parent>miro_gmbl::gmbl</parent>
        <child>miro_head::head</child>
        <axis>
          <xyz>0 1 0</xyz>
          <limit>
            <lower>-1.57</lower>
            <upper>1.57</upper>
          </limit>
          <dynamics>
            <spring_stiffness>0.1</spring_stiffness>
            <spring_reference>-0.5</spring_reference>
            <friction>0.01</friction>
            <damping>0.1</damping>
          </dynamics>
        </axis>
      </joint>
      <frame name='miro_head::__model__' attached_to='miro_head::head'>
        <pose relative_to='__model__'>0 0 0 0 -0 0</pose>
      </frame>
      <link name='miro_head::head'>
        <inertial>
          <pose>-0.002 0 0.221 0 -0 0</pose>
          <mass>0.261799</mass>
          <inertia>
            <ixx>0.00043633</ixx>
            <ixy>0</ixy>
            <ixz>0</ixz>
            <iyy>0.00043633</iyy>
            <iyz>0</iyz>
            <izz>0.00043633</izz>
          </inertia>
        </inertial>
        <visual name='visual_head_lower'>
          <pose>0 0 0 0 -0 0</pose>
          <geometry>
            <mesh>
              <uri>model://miro_model/meshes/head_lower.dae</uri>
            </mesh>
          </geometry>
          <material>
            <script>
              <uri>file://media/materials/scripts/gazebo.material</uri>
              <name>Gazebo/White</name>
            </script>
          </material>
        </visual>
        <collision name='collision_head_lower'>
          <pose>0 0 0 0 -0 0</pose>
          <geometry>
            <mesh>
              <uri>model://miro_model/meshes/head_lower_collision.dae</uri>
            </mesh>
          </geometry>
          <surface>
            <friction>
              <ode>
                <mu>0.1</mu>
                <mu2>0.1</mu2>
              </ode>
              <torsional>
                <ode/>
              </torsional>
            </friction>
            <contact>
              <ode/>
            </contact>
            <bounce/>
          </surface>
          <max_contacts>10</max_contacts>
        </collision>
        <visual name='visual_head_upper'>
          <pose>0 0 0 0 -0 0</pose>
          <geometry>
            <mesh>
              <uri>model://miro_model/meshes/head_upper.dae</uri>
            </mesh>
          </geometry>
          <material>
            <script>
              <uri>file://media/materials/scripts/gazebo.material</uri>
              <name>Gazebo/White</name>
            </script>
          </material>
        </visual>
        <collision name='collision_head_upper'>
          <pose>0 0 0 0 -0 0</pose>
          <geometry>
            <mesh>
              <uri>model://miro_model/meshes/head_upper_collision.dae</uri>
            </mesh>
          </geometry>
          <surface>
            <friction>
              <ode>
                <mu>0.1</mu>
                <mu2>0.1</mu2>
              </ode>
              <torsional>
                <ode/>
              </torsional>
            </friction>
            <contact>
              <ode/>
            </contact>
            <bounce/>
          </surface>
          <max_contacts>10</max_contacts>
        </collision>
        <visual name='visual_eyelid_lower_lh'>
          <pose>0 0 0 0 -0 0</pose>
          <geometry>
            <mesh>
              <uri>model://miro_model/meshes/eyelid_lower_lh.dae</uri>
            </mesh>
          </geometry>
          <material>
            <script>
              <uri>file://media/materials/scripts/gazebo.material</uri>
              <name>Gazebo/White</name>
            </script>
          </material>
        </visual>
        <visual name='visual_eyelid_lower_rh'>
          <pose>0 0 0 0 -0 0</pose>
          <geometry>
            <mesh>
              <uri>model://miro_model/meshes/eyelid_lower_rh.dae</uri>
            </mesh>
          </geometry>
          <material>
            <script>
              <uri>file://media/materials/scripts/gazebo.material</uri>
              <name>Gazebo/White</name>
            </script>
          </material>
        </visual>
        <visual name='visual_nose'>
          <pose>0 0 0 0 -0 0</pose>
          <geometry>
            <mesh>
              <uri>model://miro_model/meshes/nose.dae</uri>
            </mesh>
          </geometry>
          <material>
            <script>
              <uri>file://media/materials/scripts/gazebo.material</uri>
              <name>Gazebo/Grey</name>
            </script>
          </material>
        </visual>
        <collision name='collision_nose'>
          <pose>0 0 0 0 -0 0</pose>
          <geometry>
            <mesh>
              <uri>model://miro_model/meshes/nose_collision.dae</uri>
            </mesh>
          </geometry>
          <surface>
            <friction>
              <ode>
                <mu>0.3</mu>
                <mu2>0.3</mu2>
              </ode>
              <torsional>
                <ode/>
              </torsional>
            </friction>
            <contact>
              <ode/>
            </contact>
            <bounce/>
          </surface>
          <max_contacts>10</max_contacts>
        </collision>
        <visual name='visual_1'>
          <pose>0.029 0.033 0.252 0 -0 0</pose>
          <geometry>
            <sphere>
              <radius>0.018</radius>
            </sphere>
          </geometry>
          <material>
            <script>
              <uri>file://media/materials/scripts/gazebo.material</uri>
              <name>Gazebo/White</name>
            </script>
          </material>
        </visual>
        <visual name='visual_2'>
          <pose>0.0315 0.036 0.254 0 -0 0</pose>
          <geometry>
            <sphere>
              <radius>0.015</radius>
            </sphere>
          </geometry>
          <material>
            <script>
              <uri>file://media/materials/scripts/gazebo.material</uri>
              <name>Gazebo/DarkGrey</name>
            </script>
          </material>
        </visual>
        <visual name='visual_3'>
          <pose>0.029 -0.033 0.252 0 -0 0</pose>
          <geometry>
            <sphere>
              <radius>0.018</radius>
            </sphere>
          </geometry>
          <material>
            <script>
              <uri>file://media/materials/scripts/gazebo.material</uri>
              <name>Gazebo/White</name>
            </script>
          </material>
        </visual>
        <visual name='visual_4'>
          <pose>0.0315 -0.036 0.254 0 -0 0</pose>
          <geometry>
            <sphere>
              <radius>0.015</radius>
            </sphere>
          </geometry>
          <material>
            <script>
              <uri>file://media/materials/scripts/gazebo.material</uri>
              <name>Gazebo/DarkGrey</name>
            </script>
          </material>
        </visual>
        <sensor name='eye_l' type='wideanglecamera'>
          <pose>0.0377 0.0431 0.2595 -0.4262 -0.6816 0.6244</pose>
          <camera>
            <horizontal_fov>2.0944</horizontal_fov>
            <image>
              <width>1280</width>
              <height>720</height>
            </image>
            <clip>
              <near>0.006</near>
              <far>100</far>
            </clip>
            <lens>
              <type>custom</type>
              <scale_to_hfov>1</scale_to_hfov>
              <custom_function>
                <c1>2</c1>
                <c2>1.25</c2>
                <c3>0</c3>
                <f>1</f>
                <fun>sin</fun>
              </custom_function>
            </lens>
          </camera>
          <always_on>1</always_on>
          <update_rate>10</update_rate>
          <visualize>0</visualize>
        </sensor>
        <sensor name='eye_r' type='wideanglecamera'>
          <pose>0.0377 -0.0431 0.2595 0.4261 -0.6816 -0.6244</pose>
          <camera>
            <horizontal_fov>2.0944</horizontal_fov>
            <image>
              <width>1280</width>
              <height>720</height>
            </image>
            <clip>
              <near>0.006</near>
              <far>100</far>
            </clip>
            <lens>
              <type>custom</type>
              <scale_to_hfov>1</scale_to_hfov>
              <custom_function>
                <c1>2</c1>
                <c2>1.25</c2>
                <c3>0</c3>
                <f>1</f>
                <fun>sin</fun>
              </custom_function>
            </lens>
          </camera>
          <always_on>1</always_on>
          <update_rate>10</update_rate>
          <visualize>0</visualize>
        </sensor>
        <sensor name='eye_l_narrow' type='camera'>
          <pose>0.0377 0.0431 0.2595 -0.4262 -0.6816 0.6244</pose>
          <camera>
            <horizontal_fov>2.0944</horizontal_fov>
            <image>
              <width>1280</width>
              <height>720</height>
            </image>
            <clip>
              <near>0.006</near>
              <far>100</far>
            </clip>
          </camera>
          <always_on>1</always_on>
          <update_rate>10</update_rate>
          <visualize>0</visualize>
        </sensor>
        <sensor name='eye_r_narrow' type='camera'>
          <pose>0.0377 -0.0431 0.2595 0.4261 -0.6816 -0.6244</pose>
          <camera>
            <horizontal_fov>2.0944</horizontal_fov>
            <image>
              <width>1280</width>
              <height>720</height>
            </image>
            <clip>
              <near>0.006</near>
              <far>100</far>
            </clip>
          </camera>
          <always_on>1</always_on>
          <update_rate>10</update_rate>
          <visualize>0</visualize>
        </sensor>
        <sensor name='gaze' type='camera'>
          <pose>0.0577 0 0.2795 0 -0.785398 0</pose>
          <camera>
            <horizontal_fov>1</horizontal_fov>
            <image>
              <width>1280</width>
              <height>720</height>
            </image>
            <clip>
              <near>0.001</near>
              <far>100</far>
            </clip>
          </camera>
          <always_on>1</always_on>
          <update_rate>10</update_rate>
          <visualize>0</visualize>
        </sensor>
        <sensor name='overhead' type='camera'>
          <pose>0 0 1 0 1.22 0</pose>
          <camera>
            <horizontal_fov>1.0472</horizontal_fov>
            <image>
              <width>1280</width>
              <height>720</height>
            </image>
            <clip>
              <near>0.01</near>
              <far>2</far>
            </clip>
          </camera>
          <always_on>1</always_on>
          <update_rate>10</update_rate>
          <visualize>0</visualize>
        </sensor>
        <sensor name='acc_head' type='imu'>
          <pose>0 0 0 0 -0 0</pose>
          <always_on>1</always_on>
          <update_rate>50</update_rate>
          <visualize>0</visualize>
          <imu/>
        </sensor>
        <sensor name='sonar' type='sonar'>
          <pose>0.1 0 0.235 3.14159 -1.57079 3.14159</pose>
          <always_on>1</always_on>
          <update_rate>50</update_rate>
          <visualize>0</visualize>
          <sonar>
            <min>0</min>
            <max>1</max>
            <radius>0.309</radius>
          </sonar>
        </sensor>
        <pose relative_to='miro_head::__model__'>0 0 0 0 -0 0</pose>
        <self_collide>0</self_collide>
        <enable_wind>0</enable_wind>
        <kinematic>0</kinematic>
      </link>
      <link name='miro_head::eyelid_lh'>
        <inertial>
          <pose>0.029 0.032 0.252 0 -0 0</pose>
          <mass>0.016755</mass>
          <inertia>
            <ixx>4.47e-06</ixx>
            <ixy>0</ixy>
            <ixz>0</ixz>
            <iyy>4.47e-06</iyy>
            <iyz>0</iyz>
            <izz>4.47e-06</izz>
          </inertia>
        </inertial>
        <visual name='visual_eyelid_lh'>
          <pose>0 0 0 0 -0 0</pose>
          <geometry>
            <mesh>
              <uri>model://miro_model/meshes/eyelid_lh.dae</uri>
            </mesh>
          </geometry>
          <material>
            <script>
              <uri>file://media/materials/scripts/gazebo.material</uri>
              <name>Gazebo/White</name>
            </script>
          </material>
        </visual>
        <pose relative_to='miro_head::__model__'>0 0 0 0 -0 0</pose>
        <self_collide>0</self_collide>
        <enable_wind>0</enable_wind>
        <kinematic>0</kinematic>
      </link>
      <link name='miro_head::eyelid_rh'>
        <inertial>
          <pose>0.029 -0.032 0.252 0 -0 0</pose>
          <mass>0.016755</mass>
          <inertia>
            <ixx>4.47e-06</ixx>
            <ixy>0</ixy>
            <ixz>0</ixz>
            <iyy>4.47e-06</iyy>
            <iyz>0</iyz>
            <izz>4.47e-06</izz>
          </inertia>
        </inertial>
        <visual name='visual_eyelid_rh'>
          <pose>0 0 0 0 -0 0</pose>
          <geometry>
            <mesh>
              <uri>model://miro_model/meshes/eyelid_rh.dae</uri>
            </mesh>
          </geometry>
          <material>
            <script>
              <uri>file://media/materials/scripts/gazebo.material</uri>
              <name>Gazebo/White</name>
            </script>
          </material>
        </visual>
        <pose relative_to='miro_head::__model__'>0 0 0 0 -0 0</pose>
        <self_collide>0</self_collide>
        <enable_wind>0</enable_wind>
        <kinematic>0</kinematic>
      </link>
      <joint name='miro_head::head_eyelid_lh' type='revolute'>
        <pose>0.029 0.032 0.252 0 -0 0</pose>
        <parent>miro_head::head</parent>
        <child>miro_head::eyelid_lh</child>
        <axis>
          <xyz>-0.675 0.675 -0.2978</xyz>
          <limit>
            <lower>-1.57</lower>
            <upper>1.57</upper>
          </limit>
          <dynamics>
            <friction>0.1</friction>
            <damping>0.1</damping>
            <spring_reference>-0.5</spring_reference>
            <spring_stiffness>0.02</spring_stiffness>
          </dynamics>
        </axis>
        <physics>
          <ode>
            <cfm_damping>1</cfm_damping>
            <implicit_spring_damper>1</implicit_spring_damper>
            <limit>
              <cfm>0</cfm>
              <erp>0.2</erp>
            </limit>
          </ode>
        </physics>
      </joint>
      <joint name='miro_head::head_eyelid_rh' type='revolute'>
        <pose>0.029 -0.032 0.252 0 -0 0</pose>
        <parent>miro_head::head</parent>
        <child>miro_head::eyelid_rh</child>
        <axis>
          <xyz>0.675 0.675 0.2978</xyz>
          <limit>
            <lower>-1.57</lower>
            <upper>1.57</upper>
          </limit>
          <dynamics>
            <friction>0.1</friction>
            <damping>0.1</damping>
            <spring_reference>-0.5</spring_reference>
            <spring_stiffness>0.02</spring_stiffness>
          </dynamics>
        </axis>
        <physics>
          <ode>
            <cfm_damping>1</cfm_damping>
            <implicit_spring_damper>1</implicit_spring_damper>
            <limit>
              <cfm>0</cfm>
              <erp>0.2</erp>
            </limit>
          </ode>
        </physics>
      </joint>
      <link name='miro_head::ear_lh'>
        <inertial>
          <pose>-0.0437 0.0474 0.2773 0 -0 0</pose>
          <mass>0.056549</mass>
          <inertia>
            <ixx>3.393e-05</ixx>
            <ixy>0</ixy>
            <ixz>0</ixz>
            <iyy>3.393e-05</iyy>
            <iyz>0</iyz>
            <izz>3.393e-05</izz>
          </inertia>
        </inertial>
        <visual name='visual_ear_lh'>
          <pose>0 0 0 0 -0 0</pose>
          <geometry>
            <mesh>
              <uri>model://miro_model/meshes/ear_lh.dae</uri>
            </mesh>
          </geometry>
          <material>
            <script>
              <uri>file://media/materials/scripts/gazebo.material</uri>
              <name>Gazebo/Grey</name>
            </script>
          </material>
        </visual>
        <collision name='collision_ear_lh'>
          <pose>0 0 0 0 -0 0</pose>
          <geometry>
            <mesh>
              <uri>model://miro_model/meshes/ear_lh_collision.dae</uri>
            </mesh>
          </geometry>
          <surface>
            <friction>
              <ode>
                <mu>0.3</mu>
                <mu2>0.3</mu2>
              </ode>
              <torsional>
                <ode/>
              </torsional>
            </friction>
            <contact>
              <ode/>
            </contact>
            <bounce/>
          </surface>
          <max_contacts>10</max_contacts>
        </collision>
        <pose relative_to='miro_head::__model__'>0 0 0 0 -0 0</pose>
        <self_collide>0</self_collide>
        <enable_wind>0</enable_wind>
        <kinematic>0</kinematic>
      </link>
      <link name='miro_head::ear_rh'>
        <inertial>
          <pose>-0.0437 -0.0474 0.2773 0 -0 0</pose>
          <mass>0.056549</mass>
          <inertia>
            <ixx>3.393e-05</ixx>
            <ixy>0</ixy>
            <ixz>0</ixz>
            <iyy>3.393e-05</iyy>
            <iyz>0</iyz>
            <izz>3.393e-05</izz>
          </inertia>
        </inertial>
        <visual name='visual_ear_rh'>
          <pose>0 0 0 0 -0 0</pose>
          <geometry>
            <mesh>
              <uri>model://miro_model/meshes/ear_rh.dae</uri>
            </mesh>
          </geometry>
          <material>
            <script>
              <uri>file://media/materials/scripts/gazebo.material</uri>
              <name>Gazebo/Grey</name>
            </script>
          </material>
        </visual>
        <collision name='collision_ear_rh'>
          <pose>0 0 0 0 -0 0</pose>
          <geometry>
            <mesh>
              <uri>model://miro_model/meshes/ear_rh_collision.dae</uri>
            </mesh>
          </geometry>
          <surface>
            <friction>
              <ode>
                <mu>0.3</mu>
                <mu2>0.3</mu2>
              </ode>
              <torsional>
                <ode/>
              </torsional>
            </friction>
            <contact>
              <ode/>
            </contact>
            <bounce/>
          </surface>
          <max_contacts>10</max_contacts>
        </collision>
        <pose relative_to='miro_head::__model__'>0 0 0 0 -0 0</pose>
        <self_collide>0</self_collide>
        <enable_wind>0</enable_wind>
        <kinematic>0</kinematic>
      </link>
      <joint name='miro_head::head_ear_lh' type='revolute'>
        <pose>-0.0437 0.0474 0.2773 0 -0 0</pose>
        <parent>miro_head::head</parent>
        <child>miro_head::ear_lh</child>
        <axis>
          <xyz>-0.573 0.4344 0.6949</xyz>
          <limit>
            <lower>-1.57</lower>
            <upper>1.57</upper>
          </limit>
          <dynamics>
            <friction>0.01</friction>
            <damping>0.001</damping>
            <spring_reference>0</spring_reference>
            <spring_stiffness>0</spring_stiffness>
          </dynamics>
        </axis>
      </joint>
      <joint name='miro_head::head_ear_rh' type='revolute'>
        <pose>-0.0437 -0.0474 0.2773 0 -0 0</pose>
        <parent>miro_head::head</parent>
        <child>miro_head::ear_rh</child>
        <axis>
          <xyz>-0.573 -0.4344 0.6949</xyz>
          <limit>
            <lower>-1.57</lower>
            <upper>1.57</upper>
          </limit>
          <dynamics>
            <friction>0.01</friction>
            <damping>0.001</damping>
            <spring_reference>0</spring_reference>
            <spring_stiffness>0</spring_stiffness>
          </dynamics>
        </axis>
      </joint>
      <plugin name='miro_model' filename='libmiro_gazebo.so'/>
      <pose>1.57977 1.54101 0.000364 -3e-05 -0.108206 1.53043</pose>
    </model>
  </world>
</sdf>
